Workbook

Sheet Flow

Sheet Stored

Sheet Decade

Sheet ΙΣΤΟΣΕΛΙΔΑ-GR(4)
B9: ΠΟΣΟΤΗΤΕΣ ΝΕΡΟΥ ΣΤΑ ΜΕΓΑΛΑ ΦΡΑΓΜΑΤΑ
L10: 46315
F11: Εισροή | H11: Αποθηκευμένη Ποσότητα | L11: Μέγιστη
E12: Χωρητι- | F12: Νερού | H12: Σημερινή | J12: Αντίστοιχη Περσινή | L12: Ποσότητα
B13: Φράγματα | E13: κότητα | F13: Τελευτ. | G13: Συνολική | I13: Πληρό- | K13: Πληρό-
F14: 24ώρου | G14: Απο 1/10 | H14: Ε.Κ.Μ. | I14: τητα | J14: Ε.Κ.Μ | K14: τητα | L14: 2026
E15: Ε.Κ.Μ | F15: Ε.Κ.Μ | G15: 2026 | I15: % | K15: % | L15: Ε.Κ.Μ | M15: Ημερομ.
B16: ΝΟΤΙΟΣ ΑΓΩΓΟΣ
B17: Κούρης | E17: 115 | F17: 0.042 | G17: 0.566 | H17: 42.226 | I17: 36.718261 | J17: 11.88 | K17: 10.330435 | L17: 48.267 | M17: 16/6
B18: Καλαβασός | E18: 17.1 | F18: 0 | G18: 0.026 | H18: 3.69 | I18: 21.578947 | J18: 1.969 | K18: 11.51462 | L18: 4.247 | M18: 17/6
B19: Λεύκαρα | E19: 13.85 | F19: 0 | G19: 0.013 | H19: 2.397 | I19: 17.306859 | J19: 2.01 | K19: 14.512635 | L19: 2.569 | M19: 17/6
B20: Διπόταμος | E20: 15.5 | F20: 0 | G20: 0.042 | H20: 3.765 | I20: 24.290323 | J20: 3.258 | K20: 21.019355 | L20: 5.941 | M20: 3/6
B21: Γερμασόγεια | E21: 13.5 | F21: 0 | G21: 0.03 | H21: 6.417 | I21: 47.533333 | J21: 0.85 | K21: 6.2962963 | L21: 8.14 | M21: 29/5
B22: Αρμίνου | E22: 4.3 | F22: 0.017 | G22: 0.366 | H22: 2.855 | I22: 66.395349 | J22: 1.767 | K22: 41.093023 | L22: 3.117 | M22: 13/5
B23: Πολεμίδια | E23: 3.4 | F23: 0 | G23: 0.011 | H23: 1.462 | I23: 43 | J23: 0.843 | K23: 24.794118 | L23: 2.198 | M23: 25/5
B24: Αχνα | E24: 6.8 | F24: 0 | G24: 0 | H24: 0.542 | I24: 7.9705882 | J24: 0.098 | K24: 1.4411765 | L24: 0.38 | M24: 30/9
B25: ΟΛΙΚΟ | E25: 189.45 | F25: 0.059 | G25: 1.054 | H25: 63.354 | I25: 33.441013 | J25: 22.675 | K25: 11.968857 | L25: 73.127 | M25: 16/6
B26: ΠΑΦΟΣ
B27: Ασπρόκρεμμος | E27: 52.375 | F27: 0.018 | G27: 0.096 | H27: 18.524 | I27: 35.368019 | J27: 5.039 | K27: 9.6210024 | L27: 22.011 | M27: 29,5
B28: Κανναβιού | E28: 17.168 | F28: 0.002 | G28: 0.112 | H28: 7.164 | I28: 41.728798 | J28: 2.085 | K28: 12.144688 | L28: 8.99 | M28: 28/5
B29: Μαυροκόλυμπος | E29: 2.18 | F29: 0.001 | G29: 0.019 | H29: 0.653 | I29: 29.954128 | J29: 0 | K29: 0 | L29: 1.974 | M29: 24/4
B30: ΟΛΙΚΟ | E30: 71.723 | F30: 0.021 | G30: 0.227 | H30: 26.341 | I30: 36.726015 | J30: 7.124 | K30: 9.9326576 | L30: 32.914 | M30: 29/5
B31: ΧΡΥΣΟΧΟΥ
B32: Ευρέτου | E32: 24 | F32: 0.002 | G32: 0.047 | H32: 9.272 | I32: 38.633333 | J32: 2.855 | K32: 11.895833 | L32: 12.036 | M32: 27/5
B33: Αργάκα | E33: 0.99 | F33: 0 | G33: 0.011 | H33: 0.441 | I33: 44.545455 | J33: 0.003 | K33: 0.3030303 | L33: 0.99 | M33: 16/3-29/5
B34: Πωμός | E34: 0.86 | F34: 0 | G34: 0.006 | H34: 0.506 | I34: 58.837209 | J34: 0.115 | K34: 13.372093 | L34: 0.86 | M34: 16/2-12/6
B35: Αγία Μαρίνα | E35: 0.298 | F35: 0 | G35: 0.014 | H35: 0.147 | I35: 49.328859 | J35: 0.055 | K35: 18.456376 | L35: 0.298 | M35: 30/3-29/5
B36: ΟΛΙΚΟ | E36: 26.148 | F36: 0.002 | G36: 0.078 | H36: 10.366 | I36: 39.643567 | J36: 3.028 | K36: 11.580236 | L36: 14.184 | M36: 27/5
B37: ΛΕΥΚΩΣΙΑ
B38: Βυζακιά | E38: 1.69 | F38: 0 | G38: 0.001 | H38: 1.198 | I38: 70.887574 | J38: 0.005 | K38: 0.29585799 | L38: 1.69 | M38: 27/4-26/5
B39: Ξυλιάτος | E39: 1.43 | F39: 0 | G39: 0.011 | H39: 1.067 | I39: 74.615385 | J39: 0.03 | K39: 2.0979021 | L39: 1.43 | M39: 23/3-29/5
B40: Καλοπαναγιώτης | E40: 0.363 | F40: 0 | G40: 0 | H40: 0.363 | I40: 100 | J40: 0.04 | K40: 11.019284 | L40: 0.363 | M40: 16/1-7/9
B41: ΟΛΙΚΟ | E41: 3.483 | F41: 0 | G41: 0.012 | H41: 2.628 | I41: 75.452196 | J41: 0.075 | K41: 2.1533161 | L41: 3.483 | M41: 27/4-26/5
B43: ΓΕΝΙΚΟ ΣΥΝΟΛΟ | E43: 290.804 | F43: 0.082 | G43: 1.371 | H43: 102.689 | I43: 0.353121 | J43: 32.902 | K43: 0.1131415 | L43: 123.443 | M43: 3/6
B44: * Ε.Σ.Ν.Α.(Ενιαίο Σχέδιο Νοτίου Αγωγού - Κούρης,Καλαβασός,Λεύκαρα,Διπόταμος,Γερμασόγεια,Πολεμίδια,Αρμίνου)
B45: Μεταφορά νερού από Αρμίνου στο φράγμα Κούρη από 01/10/2026 - | J45: 0 | K45: Ε.Κ.Μ.
B46: Ε.Κ.Μ. - Εκατομμύρια Kυβικά Mέτρα.
B48: ΕΙΣΡΟΗ ΝΕΡΟΥ ΤΗΝ ΤΕΛΕΥΤΑΙΑ ΔΕΚΑΕΤΙΑ ( Ε.Κ.Μ. )
C49: 16/17 | D49: 17/18 | E49: 18/19 | F49: 19/20 | G49: 20/21 | H49: 21/22 | I49: 22/23 | J49: 23/24 | K49: 24/25 | L49: 25/26 | M49: 26/27
B50: Οκτώβρη | C50: 0.247 | D50: 0.142 | E50: 0.858 | F50: 2.4298378 | G50: 0.165 | H50: 0.084 | I50: 3.946 | J50: 0.583 | K50: 0 | L50: 0.095 | M50: 1.371
...

Sheet sorted
B1: Φράγματα | E1: Χωρητικότητα | F1: Τελευταια ροή | G1: Συνολική Απο 1/10 | H1: Σημερινή Πληροτητα | J1: Αντιστοιχη Περσινη | L1: Μεγιστη Πληροτητα κατά το 2025 | M1: Συνολική Χωρητικότητα | N1: Αποθηκευμενη Ποσότητα
E2: Ε.Κ.Μ | F2: Ε.Κ.Μ | G2: 2025 | I2: % | J2: Ε.Κ.Μ | K2: % | L2: Ε.Κ.Μ
B3: ='ΙΣΤΟΣΕΛΙΔΑ-GR(4)'!B17:D17 -> Κούρης | C3: orted | E3: ='ΙΣΤΟΣΕΛΙΔΑ-GR(4)'!E17 -> 115 | F3: ='ΙΣΤΟΣΕΛΙΔΑ-GR(4)'!F17 -> 0.042 | G3: ='ΙΣΤΟΣΕΛΙΔΑ-GR(4)'!G17 -> 0.566 | H3: ='ΙΣΤΟΣΕΛΙΔΑ-GR(4)'!H17 -> 42.226 | I3: ='ΙΣΤΟΣΕΛΙΔΑ-GR(4)'!I17 -> 36.718261 | J3: ='ΙΣΤΟΣΕΛΙΔΑ-GR(4)'!J17 -> 11.88 | K3: ='ΙΣΤΟΣΕΛΙΔΑ-GR(4)'!K17 -> 10.330435 | L3: ='ΙΣΤΟΣΕΛΙΔΑ-GR(4)'!L17 -> 48.267 | M3: =E$21 -> 290.804 | N3: =H$21 -> 102.689
B4: ='ΙΣΤΟΣΕΛΙΔΑ-GR(4)'!B27:D27 -> Ασπρόκρεμμος | C4: Ασπρόκρεμμος | E4: ='ΙΣΤΟΣΕΛΙΔΑ-GR(4)'!E27 -> 52.375 | F4: ='ΙΣΤΟΣΕΛΙΔΑ-GR(4)'!F27 -> 0.018 | G4: ='ΙΣΤΟΣΕΛΙΔΑ-GR(4)'!G27 -> 0.096 | H4: ='ΙΣΤΟΣΕΛΙΔΑ-GR(4)'!H27 -> 18.524 | I4: ='ΙΣΤΟΣΕΛΙΔΑ-GR(4)'!I27 -> 35.368019 | J4: ='ΙΣΤΟΣΕΛΙΔΑ-GR(4)'!J27 -> 5.039 | K4: ='ΙΣΤΟΣΕΛΙΔΑ-GR(4)'!K27 -> 9.6210024 | L4: ='ΙΣΤΟΣΕΛΙΔΑ-GR(4)'!L27 -> 22.011 | M4: =E$21 -> 290.804 | N4: =H$21 -> 102.689
B5: ='ΙΣΤΟΣΕΛΙΔΑ-GR(4)'!B32:D32 -> Ευρέτου | C5: Ευρέτου | E5: ='ΙΣΤΟΣΕΛΙΔΑ-GR(4)'!E32 -> 24 | F5: ='ΙΣΤΟΣΕΛΙΔΑ-GR(4)'!F32 -> 0.002 | G5: ='ΙΣΤΟΣΕΛΙΔΑ-GR(4)'!G32 -> 0.047 | H5: ='ΙΣΤΟΣΕΛΙΔΑ-GR(4)'!H32 -> 9.272 | I5: ='ΙΣΤΟΣΕΛΙΔΑ-GR(4)'!I32 -> 38.633333 | J5: ='ΙΣΤΟΣΕΛΙΔΑ-GR(4)'!J32 -> 2.855 | K5: ='ΙΣΤΟΣΕΛΙΔΑ-GR(4)'!K32 -> 11.895833 | L5: ='ΙΣΤΟΣΕΛΙΔΑ-GR(4)'!L32 -> 12.036 | M5: =E$21 -> 290.804 | N5: =H$21 -> 102.689
B6: ='ΙΣΤΟΣΕΛΙΔΑ-GR(4)'!B28:D28 -> Κανναβιού | C6: Κανναβιού | E6: ='ΙΣΤΟΣΕΛΙΔΑ-GR(4)'!E28 -> 17.168 | F6: ='ΙΣΤΟΣΕΛΙΔΑ-GR(4)'!F28 -> 0.002 | G6: ='ΙΣΤΟΣΕΛΙΔΑ-GR(4)'!G28 -> 0.112 | H6: ='ΙΣΤΟΣΕΛΙΔΑ-GR(4)'!H28 -> 7.164 | I6: ='ΙΣΤΟΣΕΛΙΔΑ-GR(4)'!I28 -> 41.728798 | J6: ='ΙΣΤΟΣΕΛΙΔΑ-GR(4)'!J28 -> 2.085 | K6: ='ΙΣΤΟΣΕΛΙΔΑ-GR(4)'!K28 -> 12.144688 | L6: ='ΙΣΤΟΣΕΛΙΔΑ-GR(4)'!L28 -> 8.99 | M6: =E$21 -> 290.804 | N6: =H$21 -> 102.689
B7: ='ΙΣΤΟΣΕΛΙΔΑ-GR(4)'!B18:D18 -> Καλαβασός | C7: Καλαβασός | E7: ='ΙΣΤΟΣΕΛΙΔΑ-GR(4)'!E18 -> 17.1 | F7: ='ΙΣΤΟΣΕΛΙΔΑ-GR(4)'!F18 -> 0 | G7: ='ΙΣΤΟΣΕΛΙΔΑ-GR(4)'!G18 -> 0.026 | H7: ='ΙΣΤΟΣΕΛΙΔΑ-GR(4)'!H18 -> 3.69 | I7: ='ΙΣΤΟΣΕΛΙΔΑ-GR(4)'!I18 -> 21.578947 | J7: ='ΙΣΤΟΣΕΛΙΔΑ-GR(4)'!J18 -> 1.969 | K7: ='ΙΣΤΟΣΕΛΙΔΑ-GR(4)'!K18 -> 11.51462 | L7: ='ΙΣΤΟΣΕΛΙΔΑ-GR(4)'!L18 -> 4.247 | M7: =E$21 -> 290.804 | N7: =H$21 -> 102.689
B8: ='ΙΣΤΟΣΕΛΙΔΑ-GR(4)'!B20:D20 -> Διπόταμος | C8: Διπόταμος | E8: ='ΙΣΤΟΣΕΛΙΔΑ-GR(4)'!E20 -> 15.5 | F8: ='ΙΣΤΟΣΕΛΙΔΑ-GR(4)'!F20 -> 0 | G8: ='ΙΣΤΟΣΕΛΙΔΑ-GR(4)'!G20 -> 0.042 | H8: ='ΙΣΤΟΣΕΛΙΔΑ-GR(4)'!H20 -> 3.765 | I8: ='ΙΣΤΟΣΕΛΙΔΑ-GR(4)'!I20 -> 24.290323 | J8: ='ΙΣΤΟΣΕΛΙΔΑ-GR(4)'!J20 -> 3.258 | K8: ='ΙΣΤΟΣΕΛΙΔΑ-GR(4)'!K20 -> 21.019355 | L8: ='ΙΣΤΟΣΕΛΙΔΑ-GR(4)'!L20 -> 5.941 | M8: =E$21 -> 290.804 | N8: =H$21 -> 102.689
B9: ='ΙΣΤΟΣΕΛΙΔΑ-GR(4)'!B19:D19 -> Λεύκαρα | C9: Λεύκαρα | E9: ='ΙΣΤΟΣΕΛΙΔΑ-GR(4)'!E19 -> 13.85 | F9: ='ΙΣΤΟΣΕΛΙΔΑ-GR(4)'!F19 -> 0 | G9: ='ΙΣΤΟΣΕΛΙΔΑ-GR(4)'!G19 -> 0.013 | H9: ='ΙΣΤΟΣΕΛΙΔΑ-GR(4)'!H19 -> 2.397 | I9: ='ΙΣΤΟΣΕΛΙΔΑ-GR(4)'!I19 -> 17.306859 | J9: ='ΙΣΤΟΣΕΛΙΔΑ-GR(4)'!J19 -> 2.01 | K9: ='ΙΣΤΟΣΕΛΙΔΑ-GR(4)'!K19 -> 14.512635 | L9: ='ΙΣΤΟΣΕΛΙΔΑ-GR(4)'!L19 -> 2.569 | M9: =E$21 -> 290.804 | N9: =H$21 -> 102.689
B10: ='ΙΣΤΟΣΕΛΙΔΑ-GR(4)'!B21:D21 -> Γερμασόγεια | C10: Γερμασόγεια | E10: ='ΙΣΤΟΣΕΛΙΔΑ-GR(4)'!E21 -> 13.5 | F10: ='ΙΣΤΟΣΕΛΙΔΑ-GR(4)'!F21 -> 0 | G10: ='ΙΣΤΟΣΕΛΙΔΑ-GR(4)'!G21 -> 0.03 | H10: ='ΙΣΤΟΣΕΛΙΔΑ-GR(4)'!H21 -> 6.417 | I10: ='ΙΣΤΟΣΕΛΙΔΑ-GR(4)'!I21 -> 47.533333 | J10: ='ΙΣΤΟΣΕΛΙΔΑ-GR(4)'!J21 -> 0.85 | K10: ='ΙΣΤΟΣΕΛΙΔΑ-GR(4)'!K21 -> 6.2962963 | L10: ='ΙΣΤΟΣΕΛΙΔΑ-GR(4)'!L21 -> 8.14 | M10: =E$21 -> 290.804 | N10: =H$21 -> 102.689
B11: ='ΙΣΤΟΣΕΛΙΔΑ-GR(4)'!B24:D24 -> Αχνα | C11: Αχνα | E11: ='ΙΣΤΟΣΕΛΙΔΑ-GR(4)'!E24 -> 6.8 | F11: ='ΙΣΤΟΣΕΛΙΔΑ-GR(4)'!F24 -> 0 | G11: ='ΙΣΤΟΣΕΛΙΔΑ-GR(4)'!G24 -> 0 | H11: ='ΙΣΤΟΣΕΛΙΔΑ-GR(4)'!H24 -> 0.542 | I11: ='ΙΣΤΟΣΕΛΙΔΑ-GR(4)'!I24 -> 7.9705882 | J11: ='ΙΣΤΟΣΕΛΙΔΑ-GR(4)'!J24 -> 0.098 | K11: ='ΙΣΤΟΣΕΛΙΔΑ-GR(4)'!K24 -> 1.4411765 | L11: ='ΙΣΤΟΣΕΛΙΔΑ-GR(4)'!L24 -> 0.38 | M11: =E$21 -> 290.804 | N11: =H$21 -> 102.689
B12: ='ΙΣΤΟΣΕΛΙΔΑ-GR(4)'!B22:D22 -> Αρμίνου | C12: Αρμίνου | E12: ='ΙΣΤΟΣΕΛΙΔΑ-GR(4)'!E22 -> 4.3 | F12: ='ΙΣΤΟΣΕΛΙΔΑ-GR(4)'!F22 -> 0.017 | G12: ='ΙΣΤΟΣΕΛΙΔΑ-GR(4)'!G22 -> 0.366 | H12: ='ΙΣΤΟΣΕΛΙΔΑ-GR(4)'!H22 -> 2.855 | I12: ='ΙΣΤΟΣΕΛΙΔΑ-GR(4)'!I22 -> 66.395349 | J12: ='ΙΣΤΟΣΕΛΙΔΑ-GR(4)'!J22 -> 1.767 | K12: ='ΙΣΤΟΣΕΛΙΔΑ-GR(4)'!K22 -> 41.093023 | L12: ='ΙΣΤΟΣΕΛΙΔΑ-GR(4)'!L22 -> 3.117 | M12: =E$21 -> 290.804 | N12: =H$21 -> 102.689
B13: ='ΙΣΤΟΣΕΛΙΔΑ-GR(4)'!B23:D23 -> Πολεμίδια | C13: Πολεμίδια | E13: ='ΙΣΤΟΣΕΛΙΔΑ-GR(4)'!E23 -> 3.4 | F13: ='ΙΣΤΟΣΕΛΙΔΑ-GR(4)'!F23 -> 0 | G13: ='ΙΣΤΟΣΕΛΙΔΑ-GR(4)'!G23 -> 0.011 | H13: ='ΙΣΤΟΣΕΛΙΔΑ-GR(4)'!H23 -> 1.462 | I13: ='ΙΣΤΟΣΕΛΙΔΑ-GR(4)'!I23 -> 43 | J13: ='ΙΣΤΟΣΕΛΙΔΑ-GR(4)'!J23 -> 0.843 | K13: ='ΙΣΤΟΣΕΛΙΔΑ-GR(4)'!K23 -> 24.794118 | L13: ='ΙΣΤΟΣΕΛΙΔΑ-GR(4)'!L23 -> 2.198 | M13: =E$21 -> 290.804 | N13: =H$21 -> 102.689
B14: ='ΙΣΤΟΣΕΛΙΔΑ-GR(4)'!B29:D29 -> Μαυροκόλυμπος | C14: Μαυροκόλυμπος | E14: ='ΙΣΤΟΣΕΛΙΔΑ-GR(4)'!E29 -> 2.18 | F14: ='ΙΣΤΟΣΕΛΙΔΑ-GR(4)'!F29 -> 0.001 | G14: ='ΙΣΤΟΣΕΛΙΔΑ-GR(4)'!G29 -> 0.019 | H14: ='ΙΣΤΟΣΕΛΙΔΑ-GR(4)'!H29 -> 0.653 | I14: ='ΙΣΤΟΣΕΛΙΔΑ-GR(4)'!I29 -> 29.954128 | J14: ='ΙΣΤΟΣΕΛΙΔΑ-GR(4)'!J29 -> 0 | K14: ='ΙΣΤΟΣΕΛΙΔΑ-GR(4)'!K29 -> 0 | L14: ='ΙΣΤΟΣΕΛΙΔΑ-GR(4)'!L29 -> 1.974 | M14: =E$21 -> 290.804 | N14: =H$21 -> 102.689
B15: ='ΙΣΤΟΣΕΛΙΔΑ-GR(4)'!B38:D38 -> Βυζακιά | C15: Βυζακιά | E15: ='ΙΣΤΟΣΕΛΙΔΑ-GR(4)'!E38 -> 1.69 | F15: ='ΙΣΤΟΣΕΛΙΔΑ-GR(4)'!F38 -> 0 | G15: ='ΙΣΤΟΣΕΛΙΔΑ-GR(4)'!G38 -> 0.001 | H15: ='ΙΣΤΟΣΕΛΙΔΑ-GR(4)'!H38 -> 1.198 | I15: ='ΙΣΤΟΣΕΛΙΔΑ-GR(4)'!I38 -> 70.887574 | J15: ='ΙΣΤΟΣΕΛΙΔΑ-GR(4)'!J38 -> 0.005 | K15: ='ΙΣΤΟΣΕΛΙΔΑ-GR(4)'!K38 -> 0.29585799 | L15: ='ΙΣΤΟΣΕΛΙΔΑ-GR(4)'!L38 -> 1.69 | M15: =E$21 -> 290.804 | N15: =H$21 -> 102.689
B16: ='ΙΣΤΟΣΕΛΙΔΑ-GR(4)'!B39:D39 -> Ξυλιάτος | C16: Ξυλιάτος | E16: ='ΙΣΤΟΣΕΛΙΔΑ-GR(4)'!E39 -> 1.43 | F16: ='ΙΣΤΟΣΕΛΙΔΑ-GR(4)'!F39 -> 0 | G16: ='ΙΣΤΟΣΕΛΙΔΑ-GR(4)'!G39 -> 0.011 | H16: ='ΙΣΤΟΣΕΛΙΔΑ-GR(4)'!H39 -> 1.067 | I16: ='ΙΣΤΟΣΕΛΙΔΑ-GR(4)'!I39 -> 74.615385 | J16: ='ΙΣΤΟΣΕΛΙΔΑ-GR(4)'!J39 -> 0.03 | K16: ='ΙΣΤΟΣΕΛΙΔΑ-GR(4)'!K39 -> 2.0979021 | L16: ='ΙΣΤΟΣΕΛΙΔΑ-GR(4)'!L39 -> 1.43 | M16: =E$21 -> 290.804 | N16: =H$21 -> 102.689
B17: ='ΙΣΤΟΣΕΛΙΔΑ-GR(4)'!B33:D33 -> Αργάκα | C17: Αργάκα | E17: ='ΙΣΤΟΣΕΛΙΔΑ-GR(4)'!E33 -> 0.99 | F17: ='ΙΣΤΟΣΕΛΙΔΑ-GR(4)'!F33 -> 0 | G17: ='ΙΣΤΟΣΕΛΙΔΑ-GR(4)'!G33 -> 0.011 | H17: ='ΙΣΤΟΣΕΛΙΔΑ-GR(4)'!H33 -> 0.441 | I17: ='ΙΣΤΟΣΕΛΙΔΑ-GR(4)'!I33 -> 44.545455 | J17: ='ΙΣΤΟΣΕΛΙΔΑ-GR(4)'!J33 -> 0.003 | K17: ='ΙΣΤΟΣΕΛΙΔΑ-GR(4)'!K33 -> 0.3030303 | L17: ='ΙΣΤΟΣΕΛΙΔΑ-GR(4)'!L33 -> 0.99 | M17: =E$21 -> 290.804 | N17: =H$21 -> 102.689
B18: ='ΙΣΤΟΣΕΛΙΔΑ-GR(4)'!B34:D34 -> Πωμός | C18: Πωμός | E18: ='ΙΣΤΟΣΕΛΙΔΑ-GR(4)'!E34 -> 0.86 | F18: ='ΙΣΤΟΣΕΛΙΔΑ-GR(4)'!F34 -> 0 | G18: ='ΙΣΤΟΣΕΛΙΔΑ-GR(4)'!G34 -> 0.006 | H18: ='ΙΣΤΟΣΕΛΙΔΑ-GR(4)'!H34 -> 0.506 | I18: ='ΙΣΤΟΣΕΛΙΔΑ-GR(4)'!I34 -> 58.837209 | J18: ='ΙΣΤΟΣΕΛΙΔΑ-GR(4)'!J34 -> 0.115 | K18: ='ΙΣΤΟΣΕΛΙΔΑ-GR(4)'!K34 -> 13.372093 | L18: ='ΙΣΤΟΣΕΛΙΔΑ-GR(4)'!L34 -> 0.86 | M18: =E$21 -> 290.804 | N18: =H$21 -> 102.689
B19: ='ΙΣΤΟΣΕΛΙΔΑ-GR(4)'!B40:D40 -> Καλοπαναγιώτης | C19: Καλοπαναγιώτης | E19: ='ΙΣΤΟΣΕΛΙΔΑ-GR(4)'!E40 -> 0.363 | F19: ='ΙΣΤΟΣΕΛΙΔΑ-GR(4)'!F40 -> 0 | G19: ='ΙΣΤΟΣΕΛΙΔΑ-GR(4)'!G40 -> 0 | H19: ='ΙΣΤΟΣΕΛΙΔΑ-GR(4)'!H40 -> 0.363 | I19: ='ΙΣΤΟΣΕΛΙΔΑ-GR(4)'!I40 -> 100 | J19: ='ΙΣΤΟΣΕΛΙΔΑ-GR(4)'!J40 -> 0.04 | K19: ='ΙΣΤΟΣΕΛΙΔΑ-GR(4)'!K40 -> 11.019284 | L19: ='ΙΣΤΟΣΕΛΙΔΑ-GR(4)'!L40 -> 0.363 | M19: =E$21 -> 290.804 | N19: =H$21 -> 102.689
B20: ='ΙΣΤΟΣΕΛΙΔΑ-GR(4)'!B35:D35 -> Αγία Μαρίνα | C20: Αγία Μαρίνα | E20: ='ΙΣΤΟΣΕΛΙΔΑ-GR(4)'!E35 -> 0.298 | F20: ='ΙΣΤΟΣΕΛΙΔΑ-GR(4)'!F35 -> 0 | G20: ='ΙΣΤΟΣΕΛΙΔΑ-GR(4)'!G35 -> 0.014 | H20: ='ΙΣΤΟΣΕΛΙΔΑ-GR(4)'!H35 -> 0.147 | I20: ='ΙΣΤΟΣΕΛΙΔΑ-GR(4)'!I35 -> 49.328859 | J20: ='ΙΣΤΟΣΕΛΙΔΑ-GR(4)'!J35 -> 0.055 | K20: ='ΙΣΤΟΣΕΛΙΔΑ-GR(4)'!K35 -> 18.456376 | L20: ='ΙΣΤΟΣΕΛΙΔΑ-GR(4)'!L35 -> 0.298 | M20: =E$21 -> 290.804 | N20: =H$21 -> 102.689
B21: ΓΕΝΙΚΟ ΣΥΝΟΛΟ | E21: =SUM(E3:E20) -> 290.804 | F21: =SUM(F3:F20) -> 0.082 | G21: =SUM(G3:G20) -> 1.371 | H21: =SUM(H3:H20) -> 102.689 | I21: =H21/E21 -> 0.353121 | J21: =SUM(J3:J20) -> 32.902 | K21: =J21/E21 -> 0.1131415 | L21: ='ΙΣΤΟΣΕΛΙΔΑ-GR(4)'!L43 -> 123.443 | M21: =E$21 -> 290.804 | N21: =H$21 -> 102.689
B26: ='ΙΣΤΟΣΕΛΙΔΑ-GR(4)'!B49 -> 0 | C26: =#REF! -> #REF! | D26: =#REF! -> #REF! | E26: ='ΙΣΤΟΣΕΛΙΔΑ-GR(4)'!C49 -> 16/17 | F26: ='ΙΣΤΟΣΕΛΙΔΑ-GR(4)'!D49 -> 17/18 | G26: ='ΙΣΤΟΣΕΛΙΔΑ-GR(4)'!E49 -> 18/19 | H26: ='ΙΣΤΟΣΕΛΙΔΑ-GR(4)'!F49 -> 19/20 | I26: ='ΙΣΤΟΣΕΛΙΔΑ-GR(4)'!G49 -> 20/21 | J26: ='ΙΣΤΟΣΕΛΙΔΑ-GR(4)'!H49 -> 21/22 | K26: ='ΙΣΤΟΣΕΛΙΔΑ-GR(4)'!I49 -> 22/23 | L26: ='ΙΣΤΟΣΕΛΙΔΑ-GR(4)'!J49 -> 23/24 | ... O26: ='ΙΣΤΟΣΕΛΙΔΑ-GR(4)'!M49 -> 26/27
B27: ='ΙΣΤΟΣΕΛΙΔΑ-GR(4)'!B50 -> Οκτώβρη | C27: =#REF! -> #REF! | D27: =#REF! -> #REF! | E27: ='ΙΣΤΟΣΕΛΙΔΑ-GR(4)'!C50 -> 0.247 | F27: ='ΙΣΤΟΣΕΛΙΔΑ-GR(4)'!D50 -> 0.142 | G27: ='ΙΣΤΟΣΕΛΙΔΑ-GR(4)'!E50 -> 0.858 | H27: ='ΙΣΤΟΣΕΛΙΔΑ-GR(4)'!F50 -> 2.4298378 | I27: ='ΙΣΤΟΣΕΛΙΔΑ-GR(4)'!G50 -> 0.165 | J27: ='ΙΣΤΟΣΕΛΙΔΑ-GR(4)'!H50 -> 0.084 | K27: ='ΙΣΤΟΣΕΛΙΔΑ-GR(4)'!I50 -> 3.946 | L27: ='ΙΣΤΟΣΕΛΙΔΑ-GR(4)'!J50 -> 0.583 | ... O27: ='ΙΣΤΟΣΕΛΙΔΑ-GR(4)'!M50 -> 1.371
B28: ='ΙΣΤΟΣΕΛΙΔΑ-GR(4)'!B51 -> Νιόβρη | C28: =#REF! -> #REF! | D28: =#REF! -> #REF! | E28: ='ΙΣΤΟΣΕΛΙΔΑ-GR(4)'!C51 -> 0.657 | F28: ='ΙΣΤΟΣΕΛΙΔΑ-GR(4)'!D51 -> 0.614 | G28: ='ΙΣΤΟΣΕΛΙΔΑ-GR(4)'!E51 -> 0.757 | H28: ='ΙΣΤΟΣΕΛΙΔΑ-GR(4)'!F51 -> 1.5453237 | I28: ='ΙΣΤΟΣΕΛΙΔΑ-GR(4)'!G51 -> 0.942 | J28: ='ΙΣΤΟΣΕΛΙΔΑ-GR(4)'!H51 -> 0.397 | K28: ='ΙΣΤΟΣΕΛΙΔΑ-GR(4)'!I51 -> 2.976 | L28: ='ΙΣΤΟΣΕΛΙΔΑ-GR(4)'!J51 -> 1.581 | ... O28: ='ΙΣΤΟΣΕΛΙΔΑ-GR(4)'!M51 -> 0
B29: ='ΙΣΤΟΣΕΛΙΔΑ-GR(4)'!B52 -> Δεκέμβρη | C29: =#REF! -> #REF! | D29: =#REF! -> #REF! | E29: ='ΙΣΤΟΣΕΛΙΔΑ-GR(4)'!C52 -> 7.424 | F29: ='ΙΣΤΟΣΕΛΙΔΑ-GR(4)'!D52 -> 0.881 | G29: ='ΙΣΤΟΣΕΛΙΔΑ-GR(4)'!E52 -> 16.665 | H29: ='ΙΣΤΟΣΕΛΙΔΑ-GR(4)'!F52 -> 30.495 | I29: ='ΙΣΤΟΣΕΛΙΔΑ-GR(4)'!G52 -> 3.107 | J29: ='ΙΣΤΟΣΕΛΙΔΑ-GR(4)'!H52 -> 11.923 | K29: ='ΙΣΤΟΣΕΛΙΔΑ-GR(4)'!I52 -> 2.922 | L29: ='ΙΣΤΟΣΕΛΙΔΑ-GR(4)'!J52 -> 2.34 | ... O29: ='ΙΣΤΟΣΕΛΙΔΑ-GR(4)'!M52 -> 0
B30: ='ΙΣΤΟΣΕΛΙΔΑ-GR(4)'!B53 -> Γενάρη | C30: =#REF! -> #REF! | D30: =#REF! -> #REF! | E30: ='ΙΣΤΟΣΕΛΙΔΑ-GR(4)'!C53 -> 21.083 | F30: ='ΙΣΤΟΣΕΛΙΔΑ-GR(4)'!D53 -> 20.661 | G30: ='ΙΣΤΟΣΕΛΙΔΑ-GR(4)'!E53 -> 118.11 | H30: ='ΙΣΤΟΣΕΛΙΔΑ-GR(4)'!F53 -> 47.74 | I30: ='ΙΣΤΟΣΕΛΙΔΑ-GR(4)'!G53 -> 12.54 | J30: ='ΙΣΤΟΣΕΛΙΔΑ-GR(4)'!H53 -> 74.614 | K30: ='ΙΣΤΟΣΕΛΙΔΑ-GR(4)'!I53 -> 8.268 | L30: ='ΙΣΤΟΣΕΛΙΔΑ-GR(4)'!J53 -> 7.3 | ... O30: ='ΙΣΤΟΣΕΛΙΔΑ-GR(4)'!M53 -> 0
B31: ='ΙΣΤΟΣΕΛΙΔΑ-GR(4)'!B54 -> Φεβράρη | C31: =#REF! -> #REF! | D31: =#REF! -> #REF! | E31: ='ΙΣΤΟΣΕΛΙΔΑ-GR(4)'!C54 -> 4.181 | F31: ='ΙΣΤΟΣΕΛΙΔΑ-GR(4)'!D54 -> 9.528 | G31: ='ΙΣΤΟΣΕΛΙΔΑ-GR(4)'!E54 -> 53.909 | H31: ='ΙΣΤΟΣΕΛΙΔΑ-GR(4)'!F54 -> 15.916 | I31: ='ΙΣΤΟΣΕΛΙΔΑ-GR(4)'!G54 -> 8.016 | J31: ='ΙΣΤΟΣΕΛΙΔΑ-GR(4)'!H54 -> 33.963 | K31: ='ΙΣΤΟΣΕΛΙΔΑ-GR(4)'!I54 -> 12.603 | L31: ='ΙΣΤΟΣΕΛΙΔΑ-GR(4)'!J54 -> 6.676 | ... O31: ='ΙΣΤΟΣΕΛΙΔΑ-GR(4)'!M54 -> 0
B32: ='ΙΣΤΟΣΕΛΙΔΑ-GR(4)'!B55 -> Μάρτη | C32: =#REF! -> #REF! | D32: =#REF! -> #REF! | E32: ='ΙΣΤΟΣΕΛΙΔΑ-GR(4)'!C55 -> 8.891 | F32: ='ΙΣΤΟΣΕΛΙΔΑ-GR(4)'!D55 -> 5.944 | G32: ='ΙΣΤΟΣΕΛΙΔΑ-GR(4)'!E55 -> 32.283 | H32: ='ΙΣΤΟΣΕΛΙΔΑ-GR(4)'!F55 -> 15.67 | I32: ='ΙΣΤΟΣΕΛΙΔΑ-GR(4)'!G55 -> 6.022 | J32: ='ΙΣΤΟΣΕΛΙΔΑ-GR(4)'!H55 -> 19.801 | K32: ='ΙΣΤΟΣΕΛΙΔΑ-GR(4)'!I55 -> 9.517 | L32: ='ΙΣΤΟΣΕΛΙΔΑ-GR(4)'!J55 -> 2.92 | ... O32: ='ΙΣΤΟΣΕΛΙΔΑ-GR(4)'!M55 -> 0
B33: ='ΙΣΤΟΣΕΛΙΔΑ-GR(4)'!B56 -> Απρίλη | C33: =#REF! -> #REF! | D33: =#REF! -> #REF! | E33: ='ΙΣΤΟΣΕΛΙΔΑ-GR(4)'!C56 -> 4.398 | F33: ='ΙΣΤΟΣΕΛΙΔΑ-GR(4)'!D56 -> 2.176 | G33: ='ΙΣΤΟΣΕΛΙΔΑ-GR(4)'!E56 -> 25.326 | H33: ='ΙΣΤΟΣΕΛΙΔΑ-GR(4)'!F56 -> 11.062 | I33: ='ΙΣΤΟΣΕΛΙΔΑ-GR(4)'!G56 -> 4.156 | J33: ='ΙΣΤΟΣΕΛΙΔΑ-GR(4)'!H56 -> 8.139 | K33: ='ΙΣΤΟΣΕΛΙΔΑ-GR(4)'!I56 -> 4.741 | L33: ='ΙΣΤΟΣΕΛΙΔΑ-GR(4)'!J56 -> 1.801 | ... O33: ='ΙΣΤΟΣΕΛΙΔΑ-GR(4)'!M56 -> 0
B34: ='ΙΣΤΟΣΕΛΙΔΑ-GR(4)'!B57 -> Μάη | C34: =#REF! -> #REF! | D34: =#REF! -> #REF! | E34: ='ΙΣΤΟΣΕΛΙΔΑ-GR(4)'!C57 -> 1.78 | F34: ='ΙΣΤΟΣΕΛΙΔΑ-GR(4)'!D57 -> 2.802 | G34: ='ΙΣΤΟΣΕΛΙΔΑ-GR(4)'!E57 -> 8.869 | H34: ='ΙΣΤΟΣΕΛΙΔΑ-GR(4)'!F57 -> 7.317 | I34: ='ΙΣΤΟΣΕΛΙΔΑ-GR(4)'!G57 -> 0.899 | J34: ='ΙΣΤΟΣΕΛΙΔΑ-GR(4)'!H57 -> 3.44 | K34: ='ΙΣΤΟΣΕΛΙΔΑ-GR(4)'!I57 -> 2.728 | L34: ='ΙΣΤΟΣΕΛΙΔΑ-GR(4)'!J57 -> 0.91 | ... O34: ='ΙΣΤΟΣΕΛΙΔΑ-GR(4)'!M57 -> 0
B35: ='ΙΣΤΟΣΕΛΙΔΑ-GR(4)'!B58 -> Ιούνη | C35: =#REF! -> #REF! | D35: =#REF! -> #REF! | E35: ='ΙΣΤΟΣΕΛΙΔΑ-GR(4)'!C58 -> 0.228 | F35: ='ΙΣΤΟΣΕΛΙΔΑ-GR(4)'!D58 -> 2.022 | G35: ='ΙΣΤΟΣΕΛΙΔΑ-GR(4)'!E58 -> 6.199 | H35: ='ΙΣΤΟΣΕΛΙΔΑ-GR(4)'!F58 -> 2.747 | I35: ='ΙΣΤΟΣΕΛΙΔΑ-GR(4)'!G58 -> 0.192 | J35: ='ΙΣΤΟΣΕΛΙΔΑ-GR(4)'!H58 -> 1.264 | K35: ='ΙΣΤΟΣΕΛΙΔΑ-GR(4)'!I58 -> 0.891 | L35: ='ΙΣΤΟΣΕΛΙΔΑ-GR(4)'!J58 -> 0.297 | ... O35: ='ΙΣΤΟΣΕΛΙΔΑ-GR(4)'!M58 -> 0
B36: ='ΙΣΤΟΣΕΛΙΔΑ-GR(4)'!B59 -> Ιούλη | C36: =#REF! -> #REF! | D36: =#REF! -> #REF! | E36: ='ΙΣΤΟΣΕΛΙΔΑ-GR(4)'!C59 -> 0 | F36: ='ΙΣΤΟΣΕΛΙΔΑ-GR(4)'!D59 -> 0.05 | G36: ='ΙΣΤΟΣΕΛΙΔΑ-GR(4)'!E59 -> 1.524 | H36: ='ΙΣΤΟΣΕΛΙΔΑ-GR(4)'!F59 -> 0.866 | I36: ='ΙΣΤΟΣΕΛΙΔΑ-GR(4)'!G59 -> 0.024 | J36: ='ΙΣΤΟΣΕΛΙΔΑ-GR(4)'!H59 -> 0.093 | K36: ='ΙΣΤΟΣΕΛΙΔΑ-GR(4)'!I59 -> 0 | L36: ='ΙΣΤΟΣΕΛΙΔΑ-GR(4)'!J59 -> 0.098 | ... O36: ='ΙΣΤΟΣΕΛΙΔΑ-GR(4)'!M59 -> 0
B37: ='ΙΣΤΟΣΕΛΙΔΑ-GR(4)'!B60 -> Αυγ.-Σεπτ. | C37: =#REF! -> #REF! | D37: =#REF! -> #REF! | E37: ='ΙΣΤΟΣΕΛΙΔΑ-GR(4)'!C60 -> 0 | F37: ='ΙΣΤΟΣΕΛΙΔΑ-GR(4)'!D60 -> 0.077 | G37: ='ΙΣΤΟΣΕΛΙΔΑ-GR(4)'!E60 -> 0.54209981 | H37: ='ΙΣΤΟΣΕΛΙΔΑ-GR(4)'!F60 -> 0.161 | I37: ='ΙΣΤΟΣΕΛΙΔΑ-GR(4)'!G60 -> 0.035 | J37: ='ΙΣΤΟΣΕΛΙΔΑ-GR(4)'!H60 -> 0.035 | K37: ='ΙΣΤΟΣΕΛΙΔΑ-GR(4)'!I60 -> 0.186 | L37: ='ΙΣΤΟΣΕΛΙΔΑ-GR(4)'!J60 -> 0.208 | ... O37: ='ΙΣΤΟΣΕΛΙΔΑ-GR(4)'!M60 -> 0
B38: ΟΛΙΚΟ | C38: =SUM(C27:C37) -> #REF! | D38: =SUM(D27:D37) -> #REF! | E38: =SUM(E27:E37) -> 48.889 | F38: =SUM(F27:F37) -> 44.897 | G38: =SUM(G27:G37) -> 265.0421 | H38: =SUM(H27:H37) -> 135.94916 | I38: =SUM(I27:I37) -> 36.098 | J38: =SUM(J27:J37) -> 153.753 | ... O38: =SUM(O27:O37) -> 1.371
B39: Ολικό μέχρι Δεκέμβριο | C39: =SUM(C27:C29) -> #REF! | D39: =SUM(D27:D29) -> #REF! | E39: =SUM(E27:E29) -> 8.328 | F39: =SUM(F27:F29) -> 1.637 | G39: =SUM(G27:G29) -> 18.28 | H39: =SUM(H27:H29) -> 34.470162 | I39: =SUM(I27:I29) -> 4.214 | J39: =SUM(J27:J29) -> 12.404 | ... O39: =SUM(O27:O29) -> 1.371
