Workbook

Sheet DAILY-ELEV-STR(1)
L1: MAJOR DAMS STORAGE | X1: W.D.D. | AK1: MAJOR DAMS ELEVATION | AS1: W.D.D.
M2: APR 2026 | X2: O&M Division | AP2: 539,50 O/F | AS2: O&M Division
D3: STORAGE | AB3: =M2 -> APR 2026 | AE3: ELEVATION | AG3: 17.5 | AL3: 22.74 | AP3: 511.3 | AV3: =AB3 -> APR 2026 | BB3: 318 | BI3: AREA | BK3: M^2
C4: DAMS | D4: KOURIS | E4: ASPROKR. | F4: EVRETOU | G4: KANNAV. | H4: KALAVAS. | I4: LEFKARA | J4: DHYPOT. | K4: GERMAS. | L4: ARMINOU | M4: AKHNA | N4: POLEM. | O4: MAVROK. | P4: VYZAKIA | Q4: XYL. | R4: ARGAKA | S4: POMOS | T4: KALOP. | U4: AY.MAR. | V4: TOTAL | W4: TOTAL | X4: CHANGE | Y4: LOSSES(-) | AC4: DAMS | AD4: KOURIS | AE4: ASPROKR. | AF4: EVRETOU | AG4: KALAVAS. | AH4: LEFKARA | AI4: DHYPOT. | AJ4: GERMAS. | AK4: ARMINOU | AL4: AKHNA | AM4: POLEM. | AN4: MAVROK. | AO4: VYZAKIA | AP4: XYL. | AQ4: ARGAKA | AR4: POMOS | AS4: KALOP. | AT4: AY.MAR. | AV4: KANNAVIOU 17,168 | AX4: TAMASOS 2,8 | AZ4: KLIROU 2,0 | BB4: SOLEA 4,454 | BE4: INFLOWS OCTOBER 2015 | BJ4: DAMS | BK4: KOURIS | BL4: ASPROKR. | BM4: EVRETOU | BN4: KALAVAS. | BO4: LEFKARA | BP4: DHYPOT. | BQ4: YERMAS. | BR4: ARMINOU | BS4: AKHNA | BT4: POLEM. | BU4: MAVROK. | BV4: VYZAKIA | BW4: XYL. | BX4: ARGAKA | BY4: POMOS | BZ4: KALOP. | CA4: AY.MAR.
B5: DATE | C5: CAPA- | D5: 115 | E5: 52.375 | F5: 24 | G5: 17.168 | H5: 17.1 | I5: 13.85 | J5: 15.5 | K5: 13.5 | L5: 4.3 | M5: 6.8 | N5: 3.4 | O5: 2.18 | P5: 1.69 | Q5: 1.43 | R5: 0.99 | S5: 0.86 | T5: 0.363 | U5: 0.298 | V5: MCM | W5: SCP | X5: OF | Y5: INFLOW(+) | AB5: DATE | AC5: CAPA- | AD5: 115 | AE5: 52.375 | AF5: 24 | AG5: 17.1 | AH5: 13.85 | AI5: 15.5 | AJ5: 13.5 | AK5: 4.3 | AL5: 6.8 | AM5: 3.4 | AN5: 2.18 | AO5: 1.69 | AP5: 1.43 | AQ5: 0.99 | AR5: 0.86 | AS5: 0.363 | AT5: 0.298 | AV5: Elev. | AW5: STOR. | AX5: Elev. | AY5: STOR. | AZ5: Elev. | BA5: STOR. | BB5: Elev. | BC5: STOR. | BI5: DATE | BJ5: CAPA- | BK5: 115 | BL5: 52.375 | BM5: 24 | BN5: 17.1 | BO5: 13.8 | BP5: 15.5 | BQ5: 13.5 | BR5: 4.3 | BS5: 6.8 | BT5: 3.4 | BU5: 2.18 | BV5: 1.69 | BW5: 1.43 | BX5: 0.99 | BY5: 0.86 | BZ5: 0.363 | CA5: 0.298
C6: CITY | X6: STORAGE | Y6: DISCR.- | AC6: CITY | BE6: Kannaviou | BF6: Tamasos | BG6: Klirou | BH6: solea | BJ6: CITY
B8: 1 | C8: W | D8: =ROUND(IF(AD8<205,SUM(-320030000,6636771*AD8,-46046*AD8^2,106.62*AD8^3),SUM(91660160,1216002*AD8,-22168*AD8^2,71.366*AD8^3))/1000000,3) -> 34.078 | E8: =ROUND((6669048.41-363409.186*AE8-307.876*AE8^2+152.3398*AE8^3)/1000000,3) -> 17.999 | F8: =ROUND((-98334930.2+3037042.21*AF8-30615.40767*AF8^2+101.23056*AF8^3)/1000000,3) -> 9.662 | G8: =AW8 -> 7.658 | H8: =ROUND((-174502023+4277428*AG8-35009.373*AG8^2+95.58911*AG8^3)/1000000-0.096,3) -> 1.964 | I8: =ROUND(IF(AH8<318,SUM(3.5242*AH8^2-2140.3*AH8+325031)/1000,SUM(70242780-813889.6*AH8+7928.716*AH8^2-35.20719*AH8^3+0.05082853*AH8^4)/1000000)-0.059,3) -> 1.926 | J8: =ROUND((-442650826+9751516.3*AI8-72042.8986*AI8^2+178.4049*AI8^3)/1000000,3)-0.071 -> 4.455 | K8: =ROUND(((4827852-139329.3*AJ8+2797.9*AJ8^2-98.98*AJ8^3+1.14*AJ8^4)/1000000),3)-0.05 -> 4.673 | L8: =ROUND((IF(AK8<424,SUM(5064.49*AK8^2-4133655.98*AK8+843517073.2),(7938.48*AK8^2-6579376.11*AK8+1363834719.7)))/1000000,3) -> 1.474 | M8: =ROUND((-8532018+1417757*AL8-72752.08*AL8^2+1191.92*AL8^3)/1000000,3) -> 0.143 | N8: =ROUND((-98293225+2791565*AM8-26671.1*AM8^2+85.56608*AM8^3)/1000000,3)-0.001 -> 1.695 | O8: =ROUND((-5101113+342273.3*AN8-5950.34*AN8^2+30.97425*AN8^3)/1000000,3)-0 -> 1.73 | P8: =ROUND((352562346-2208805*AO8+3459.655*AO8^2)/1000000,3)-0 -> 1.074 | Q8: =ROUND((426242189-1669663*AP8+1635.186*AP8^2)/1000000,3)+0.033 -> 1.43 | R8: =ROUND((2823894-25900.1*AQ8-1177.84*AQ8^2+13.979*AQ8^3)/1000000,3)-0.005 -> 0.99 | S8: =ROUND((-11518534+483790.5*AR8-6823.11*AR8^2+32.24883*AR8^3)/1000000,3)+0 -> 0.86 | T8: =ROUND((406066983-1465679*AS8+1322.517*AS8^2)/1000000,3)-0.001 -> 0.363 | U8: =ROUND((-13395930+388944*AT8-3702.68*AT8^2+11.59891*AT8^3)/1000000,3)-0 -> 0.298 | V8: =SUM(D8:U8) -> 92.472 | W8: =D8+H8+I8+J8+K8+L8+N8+M8 -> 50.408 | AB8: =B8 -> 1 | AC8: =C8 -> W | AD8: 212.66 | AE8: 61.05 | AF8: 149.46 | AG8: 150.2 | AH8: 326.77 | AI8: 161.17 | AJ8: 75.54 | AK8: 424.92 | AL8: =$AL$3+3.94 -> 26.68 | AM8: 129.15 | AN8: 109.7 | AO8: 336.75 | AP8: 539.5 | AQ8: 88.49 | AR8: 99.79 | AS8: 571.1 | AT8: 139.6 | AV8: 400.63 | AW8: 7.658 | AX8: 404.95 | AY8: 2.785 | AZ8: 397.8 | BA8: 2 | BB8: 359.5 | BC8: =(2261.87*BB8^2-1423337.72*BB8+223819398.05)/1000000 -> 4.454132 | BI8: 1 | BK8: =-4552010+77862.43*AD8-528.064*AD8^2+1.3857*AD8^3 -> 1451726 | BL8: =-3210651+145404.1*AE8-2052.163*AE8^2+14.3568*AE8^3 -> 1284388.1 | BM8: =IF(BK8<140,-737886.6-3612.887*AF8+84.47319*AF8^2,7040924-115283.7*AF8+485.2715*AF8^2) -> 650758.47 | BN8: =4001977-66502.13*AG8+275.558*AG8^2 -> 229956.58 | BO8: =12256870-84903.96*AH8+146.7551*AH8^2 -> 183111.94 | BP8: =9095248-135970.3*AI8+510.0572*AI8^2 -> 430042.7 | BQ8: =IF(BO8<73.2,-180.3+3.1*AJ8,312.46-10.83*AJ8+0.098*AJ8^2)*10000 -> 535783.77 | BR8: =(219.28*AK8^2-173172.2*AK8+34168761.89) -> 176971.03 | BS8: =5190570-498758.9*AL8+14528.53*AL8^2-112.5*AL8^3 -> 88880.707 | BT8: =(207.86-3.07416*AM8+0.00297*AM8^2+0.000073*AM8^3)*10000 -> 176266.02 | BU8: =(412.37-12.56*AN8+0.12278*AN8^2-0.000376*AN8^3)*10000 -> 157110.53 | BV8: =(5708324-41094.23*AO8+72.7745*AO8^2) -> 122511.28 | BW8: =(1307.749-5.30998*AP8+0.005386*AP8^2)*10000 -> 106652.97 | BX8: =(33.36079-1.57235*AQ8+0.020673*AQ8^2-0.000067*AQ8^3)*10000 -> 96774.683 | BY8: =(-106.619+3.872392*AR8-0.0491*AR8^2+0.000219*AR8^3)*10000 -> 84902.277 | BZ8: =(-2923.33+10.10447*AS8-0.00872*AS8^2)*10000 -> 32593.858 | CA8: =(149.6647-3.26844*AT8+0.02264*AT8^2-0.000048*AT8^3)*10000 -> 40161.559
B9: 2 | C9: T | D9: =ROUND(IF(AD9<205,SUM(-320030000,6636771*AD9,-46046*AD9^2,106.62*AD9^3),SUM(91660160,1216002*AD9,-22168*AD9^2,71.366*AD9^3))/1000000,3) -> 34.447 | E9: =ROUND((6669048.41-363409.186*AE9-307.876*AE9^2+152.3398*AE9^3)/1000000,3) -> 18.155 | F9: =ROUND((-98334930.2+3037042.21*AF9-30615.40767*AF9^2+101.23056*AF9^3)/1000000,3) -> 9.756 | G9: =AW9 -> 7.737 | H9: =ROUND((-174502023+4277428*AG9-35009.373*AG9^2+95.58911*AG9^3)/1000000-0.096,3) -> 2.034 | I9: =ROUND(IF(AH9<318,SUM(3.5242*AH9^2-2140.3*AH9+325031)/1000,SUM(70242780-813889.6*AH9+7928.716*AH9^2-35.20719*AH9^3+0.05082853*AH9^4)/1000000)-0.059,3) -> 1.944 | J9: =ROUND((-442650826+9751516.3*AI9-72042.8986*AI9^2+178.4049*AI9^3)/1000000,3)-0.071 -> 4.507 | K9: =ROUND(((4827852-139329.3*AJ9+2797.9*AJ9^2-98.98*AJ9^3+1.14*AJ9^4)/1000000),3)-0.05 -> 4.796 | L9: =ROUND((IF(AK9<424,SUM(5064.49*AK9^2-4133655.98*AK9+843517073.2),(7938.48*AK9^2-6579376.11*AK9+1363834719.7)))/1000000,3) -> 1.51 | M9: =ROUND((-8532018+1417757*AL9-72752.08*AL9^2+1191.92*AL9^3)/1000000,3) -> 0.143 | N9: =ROUND((-98293225+2791565*AM9-26671.1*AM9^2+85.56608*AM9^3)/1000000,3)-0 -> 1.733 | O9: =ROUND((-5101113+342273.3*AN9-5950.34*AN9^2+30.97425*AN9^3)/1000000,3)-0 -> 1.734 | P9: =ROUND((352562346-2208805*AO9+3459.655*AO9^2)/1000000,3)-0 -> 1.105 | Q9: =ROUND((426242189-1669663*AP9+1635.186*AP9^2)/1000000,3)+0.033 -> 1.43 | R9: =ROUND((2823894-25900.1*AQ9-1177.84*AQ9^2+13.979*AQ9^3)/1000000,3)-0.005 -> 0.99 | S9: =ROUND((-11518534+483790.5*AR9-6823.11*AR9^2+32.24883*AR9^3)/1000000,3)+0 -> 0.86 | T9: =ROUND((406066983-1465679*AS9+1322.517*AS9^2)/1000000,3)-0.001 -> 0.363 | U9: =ROUND((-13395930+388944*AT9-3702.68*AT9^2+11.59891*AT9^3)/1000000,3)-0 -> 0.298 | V9: =SUM(D9:U9) -> 93.542 | W9: =D9+H9+I9+J9+K9+L9+N9+M9 -> 51.114 | AB9: =B9 -> 2 | AC9: =C9 -> T | AD9: 212.91 | AE9: 61.17 | AF9: 149.6 | AG9: 150.5 | AH9: 326.87 | AI9: 161.29 | AJ9: 75.76 | AK9: 425.13 | AL9: =$AL$3+3.94 -> 26.68 | AM9: 129.35 | AN9: 109.73 | AO9: 337 | AP9: 539.5 | AQ9: 88.49 | AR9: 99.79 | AS9: 571.1 | AT9: 139.6 | AV9: 400.78 | AW9: 7.737 | AX9: 405 | AY9: 2.8 | AZ9: 397.8 | BA9: 2 | BB9: 359.5 | BC9: =(2261.87*BB9^2-1423337.72*BB9+223819398.05)/1000000 -> 4.454132 | BI9: 2 | BK9: =-4552010+77862.43*AD9-528.064*AD9^2+1.3857*AD9^3 -> 1462065.3 | BL9: =-3210651+145404.1*AE9-2052.163*AE9^2+14.3568*AE9^3 -> 1291040 | BM9: =IF(BK9<140,-737886.6-3612.887*AF9+84.47319*AF9^2,7040924-115283.7*AF9+485.2715*AF9^2) -> 654936.29 | BN9: =4001977-66502.13*AG9+275.558*AG9^2 -> 234864.02 | BO9: =12256870-84903.96*AH9+146.7551*AH9^2 -> 184214.04 | BP9: =9095248-135970.3*AI9+510.0572*AI9^2 -> 433463.03 | BQ9: =IF(BO9<73.2,-180.3+3.1*AJ9,312.46-10.83*AJ9+0.098*AJ9^2)*10000 -> 544578.05 | BR9: =(219.28*AK9^2-173172.2*AK9+34168761.89) -> 179748.65 | BS9: =5190570-498758.9*AL9+14528.53*AL9^2-112.5*AL9^3 -> 88880.707 | BT9: =(207.86-3.07416*AM9+0.00297*AM9^2+0.000073*AM9^3)*10000 -> 178970.22 | BU9: =(412.37-12.56*AN9+0.12278*AN9^2-0.000376*AN9^3)*10000 -> 157351.57 | BV9: =(5708324-41094.23*AO9+72.7745*AO9^2) -> 124495.68 | BW9: =(1307.749-5.30998*AP9+0.005386*AP9^2)*10000 -> 106652.97 | BX9: =(33.36079-1.57235*AQ9+0.020673*AQ9^2-0.000067*AQ9^3)*10000 -> 96774.683 | BY9: =(-106.619+3.872392*AR9-0.0491*AR9^2+0.000219*AR9^3)*10000 -> 84902.277 | BZ9: =(-2923.33+10.10447*AS9-0.00872*AS9^2)*10000 -> 32593.858 | CA9: =(149.6647-3.26844*AT9+0.02264*AT9^2-0.000048*AT9^3)*10000 -> 40161.559
B10: 3 | C10: F | D10: =ROUND(IF(AD10<205,SUM(-320030000,6636771*AD10,-46046*AD10^2,106.62*AD10^3),SUM(91660160,1216002*AD10,-22168*AD10^2,71.366*AD10^3))/1000000,3) -> 35.014 | E10: =ROUND((6669048.41-363409.186*AE10-307.876*AE10^2+152.3398*AE10^3)/1000000,3) -> 18.3 | F10: =ROUND((-98334930.2+3037042.21*AF10-30615.40767*AF10^2+101.23056*AF10^3)/1000000,3) -> 9.83 | G10: =AW10 -> 7.779 | H10: =ROUND((-174502023+4277428*AG10-35009.373*AG10^2+95.58911*AG10^3)/1000000-0.096,3) -> 2.166 | I10: =ROUND(IF(AH10<318,SUM(3.5242*AH10^2-2140.3*AH10+325031)/1000,SUM(70242780-813889.6*AH10+7928.716*AH10^2-35.20719*AH10^3+0.05082853*AH10^4)/1000000)-0.059,3) -> 2.019 | J10: =ROUND((-442650826+9751516.3*AI10-72042.8986*AI10^2+178.4049*AI10^3)/1000000,3)-0.071 -> 4.604 | K10: =ROUND(((4827852-139329.3*AJ10+2797.9*AJ10^2-98.98*AJ10^3+1.14*AJ10^4)/1000000),3)-0.05 -> 5.077 | L10: =ROUND((IF(AK10<424,SUM(5064.49*AK10^2-4133655.98*AK10+843517073.2),(7938.48*AK10^2-6579376.11*AK10+1363834719.7)))/1000000,3) -> 1.574 | M10: =ROUND((-8532018+1417757*AL10-72752.08*AL10^2+1191.92*AL10^3)/1000000,3) -> 0.143 | N10: =ROUND((-98293225+2791565*AM10-26671.1*AM10^2+85.56608*AM10^3)/1000000,3)-0 -> 1.75 | O10: =ROUND((-5101113+342273.3*AN10-5950.34*AN10^2+30.97425*AN10^3)/1000000,3)-0 -> 1.75 | P10: =ROUND((352562346-2208805*AO10+3459.655*AO10^2)/1000000,3)-0 -> 1.142 | Q10: =ROUND((426242189-1669663*AP10+1635.186*AP10^2)/1000000,3)+0.033 -> 1.43 | R10: =ROUND((2823894-25900.1*AQ10-1177.84*AQ10^2+13.979*AQ10^3)/1000000,3)-0.005 -> 0.99 | S10: =ROUND((-11518534+483790.5*AR10-6823.11*AR10^2+32.24883*AR10^3)/1000000,3)+0 -> 0.86 | T10: =ROUND((406066983-1465679*AS10+1322.517*AS10^2)/1000000,3)-0.001 -> 0.363 | U10: =ROUND((-13395930+388944*AT10-3702.68*AT10^2+11.59891*AT10^3)/1000000,3)-0 -> 0.298 | V10: =SUM(D10:U10) -> 95.089 | W10: =D10+H10+I10+J10+K10+L10+N10+M10 -> 52.347 | AB10: =B10 -> 3 | AC10: =C10 -> F | AD10: 213.29 | AE10: 61.28 | AF10: 149.71 | AG10: 151.05 | AH10: 327.27 | AI10: 161.51 | AJ10: 76.25 | AK10: 425.5 | AL10: =$AL$3+3.94 -> 26.68 | AM10: 129.44 | AN10: 109.83 | AO10: 337.3 | AP10: 539.5 | AQ10: 88.49 | AR10: 99.79 | AS10: 571.1 | AT10: 139.6 | AV10: 400.86 | AW10: 7.779 | AX10: 405 | AY10: 2.8 | AZ10: 397.8 | BA10: 2 | BB10: 359.5 | BC10: =(2261.87*BB10^2-1423337.72*BB10+223819398.05)/1000000 -> 4.454132 | BI10: 3 | BK10: =-4552010+77862.43*AD10-528.064*AD10^2+1.3857*AD10^3 -> 1477866.5 | BL10: =-3210651+145404.1*AE10-2052.163*AE10^2+14.3568*AE10^3 -> 1297152.3 | BM10: =IF(BK10<140,-737886.6-3612.887*AF10+84.47319*AF10^2,7040924-115283.7*AF10+485.2715*AF10^2) -> 658232.21 | BN10: =4001977-66502.13*AG10+275.558*AG10^2 -> 243989.84 | BO10: =12256870-84903.96*AH10+146.7551*AH10^2 -> 188651.81 | BP10: =9095248-135970.3*AI10+510.0572*AI10^2 -> 439771.79 | BQ10: =IF(BO10<73.2,-180.3+3.1*AJ10,312.46-10.83*AJ10+0.098*AJ10^2)*10000 -> 564506.25 | BR10: =(219.28*AK10^2-173172.2*AK10+34168761.89) -> 184689.61 | BS10: =5190570-498758.9*AL10+14528.53*AL10^2-112.5*AL10^3 -> 88880.707 | BT10: =(207.86-3.07416*AM10+0.00297*AM10^2+0.000073*AM10^3)*10000 -> 180195.28 | BU10: =(412.37-12.56*AN10+0.12278*AN10^2-0.000376*AN10^3)*10000 -> 158154.88 | BV10: =(5708324-41094.23*AO10+72.7745*AO10^2) -> 126888.97 | BW10: =(1307.749-5.30998*AP10+0.005386*AP10^2)*10000 -> 106652.97 | BX10: =(33.36079-1.57235*AQ10+0.020673*AQ10^2-0.000067*AQ10^3)*10000 -> 96774.683 | BY10: =(-106.619+3.872392*AR10-0.0491*AR10^2+0.000219*AR10^3)*10000 -> 84902.277 | BZ10: =(-2923.33+10.10447*AS10-0.00872*AS10^2)*10000 -> 32593.858 | CA10: =(149.6647-3.26844*AT10+0.02264*AT10^2-0.000048*AT10^3)*10000 -> 40161.559
B11: 4 | C11: S | AB11: =B11 -> 4 | AC11: =C11 -> S | BI11: 4 | BK11: =-4552010+77862.43*AD11-528.064*AD11^2+1.3857*AD11^3 -> -4552010 | BL11: =-3210651+145404.1*AE11-2052.163*AE11^2+14.3568*AE11^3 -> -3210651 | BM11: =IF(BK11<140,-737886.6-3612.887*AF11+84.47319*AF11^2,7040924-115283.7*AF11+485.2715*AF11^2) -> -737886.6 | BN11: =4001977-66502.13*AG11+275.558*AG11^2 -> 4001977 | BO11: =12256870-84903.96*AH11+146.7551*AH11^2 -> 12256870 | BP11: =9095248-135970.3*AI11+510.0572*AI11^2 -> 9095248 | BQ11: =IF(BO11<73.2,-180.3+3.1*AJ11,312.46-10.83*AJ11+0.098*AJ11^2)*10000 -> 3124600 | BR11: =(219.28*AK11^2-173172.2*AK11+34168761.89) -> 34168762 | BS11: =5190570-498758.9*AL11+14528.53*AL11^2-112.5*AL11^3 -> 5190570 | BT11: =(207.86-3.07416*AM11+0.00297*AM11^2+0.000073*AM11^3)*10000 -> 2078600 | BU11: =(412.37-12.56*AN11+0.12278*AN11^2-0.000376*AN11^3)*10000 -> 4123700 | BV11: =(5708324-41094.23*AO11+72.7745*AO11^2) -> 5708324 | BW11: =(1307.749-5.30998*AP11+0.005386*AP11^2)*10000 -> 13077490 | BX11: =(33.36079-1.57235*AQ11+0.020673*AQ11^2-0.000067*AQ11^3)*10000 -> 333607.9 | BY11: =(-106.619+3.872392*AR11-0.0491*AR11^2+0.000219*AR11^3)*10000 -> -1066190 | BZ11: =(-2923.33+10.10447*AS11-0.00872*AS11^2)*10000 -> -29233300 | CA11: =(149.6647-3.26844*AT11+0.02264*AT11^2-0.000048*AT11^3)*10000 -> 1496647
B12: 5 | C12: S | AB12: =B12 -> 5 | AC12: =C12 -> S | BI12: 5 | BK12: =-4552010+77862.43*AD12-528.064*AD12^2+1.3857*AD12^3 -> -4552010 | BL12: =-3210651+145404.1*AE12-2052.163*AE12^2+14.3568*AE12^3 -> -3210651 | BM12: =IF(BK12<140,-737886.6-3612.887*AF12+84.47319*AF12^2,7040924-115283.7*AF12+485.2715*AF12^2) -> -737886.6 | BN12: =4001977-66502.13*AG12+275.558*AG12^2 -> 4001977 | BO12: =12256870-84903.96*AH12+146.7551*AH12^2 -> 12256870 | BP12: =9095248-135970.3*AI12+510.0572*AI12^2 -> 9095248 | BQ12: =IF(BO12<73.2,-180.3+3.1*AJ12,312.46-10.83*AJ12+0.098*AJ12^2)*10000 -> 3124600 | BR12: =(219.28*AK12^2-173172.2*AK12+34168761.89) -> 34168762 | BS12: =5190570-498758.9*AL12+14528.53*AL12^2-112.5*AL12^3 -> 5190570 | BT12: =(207.86-3.07416*AM12+0.00297*AM12^2+0.000073*AM12^3)*10000 -> 2078600 | BU12: =(412.37-12.56*AN12+0.12278*AN12^2-0.000376*AN12^3)*10000 -> 4123700 | BV12: =(5708324-41094.23*AO12+72.7745*AO12^2) -> 5708324 | BW12: =(1307.749-5.30998*AP12+0.005386*AP12^2)*10000 -> 13077490 | BX12: =(33.36079-1.57235*AQ12+0.020673*AQ12^2-0.000067*AQ12^3)*10000 -> 333607.9 | BY12: =(-106.619+3.872392*AR12-0.0491*AR12^2+0.000219*AR12^3)*10000 -> -1066190 | BZ12: =(-2923.33+10.10447*AS12-0.00872*AS12^2)*10000 -> -29233300 | CA12: =(149.6647-3.26844*AT12+0.02264*AT12^2-0.000048*AT12^3)*10000 -> 1496647
B13: 6 | C13: M | D13: =ROUND(IF(AD13<205,SUM(-320030000,6636771*AD13,-46046*AD13^2,106.62*AD13^3),SUM(91660160,1216002*AD13,-22168*AD13^2,71.366*AD13^3))/1000000,3) -> 36.213 | E13: =ROUND((6669048.41-363409.186*AE13-307.876*AE13^2+152.3398*AE13^3)/1000000,3) -> 18.857 | F13: =ROUND((-98334930.2+3037042.21*AF13-30615.40767*AF13^2+101.23056*AF13^3)/1000000,3) -> 10.055 | G13: =AW13 -> 7.929 | H13: =ROUND((-174502023+4277428*AG13-35009.373*AG13^2+95.58911*AG13^3)/1000000-0.096,3) -> 2.418 | I13: =ROUND(IF(AH13<318,SUM(3.5242*AH13^2-2140.3*AH13+325031)/1000,SUM(70242780-813889.6*AH13+7928.716*AH13^2-35.20719*AH13^3+0.05082853*AH13^4)/1000000)-0.059,3) -> 2.161 | J13: =ROUND((-442650826+9751516.3*AI13-72042.8986*AI13^2+178.4049*AI13^3)/1000000,3)-0.071 -> 4.869 | K13: =ROUND(((4827852-139329.3*AJ13+2797.9*AJ13^2-98.98*AJ13^3+1.14*AJ13^4)/1000000),3)-0.05 -> 5.568 | L13: =ROUND((IF(AK13<424,SUM(5064.49*AK13^2-4133655.98*AK13+843517073.2),(7938.48*AK13^2-6579376.11*AK13+1363834719.7)))/1000000,3) -> 1.733 | M13: =ROUND((-8532018+1417757*AL13-72752.08*AL13^2+1191.92*AL13^3)/1000000,3) -> 0.143 | N13: =ROUND((-98293225+2791565*AM13-26671.1*AM13^2+85.56608*AM13^3)/1000000,3)-0 -> 1.786 | O13: =ROUND((-5101113+342273.3*AN13-5950.34*AN13^2+30.97425*AN13^3)/1000000,3)-0 -> 1.78 | P13: =ROUND((352562346-2208805*AO13+3459.655*AO13^2)/1000000,3)-0 -> 1.244 | Q13: =ROUND((426242189-1669663*AP13+1635.186*AP13^2)/1000000,3)+0.033 -> 1.43 | R13: =ROUND((2823894-25900.1*AQ13-1177.84*AQ13^2+13.979*AQ13^3)/1000000,3)-0.005 -> 0.99 | S13: =ROUND((-11518534+483790.5*AR13-6823.11*AR13^2+32.24883*AR13^3)/1000000,3)+0 -> 0.86 | T13: =ROUND((406066983-1465679*AS13+1322.517*AS13^2)/1000000,3)-0.001 -> 0.363 | U13: =ROUND((-13395930+388944*AT13-3702.68*AT13^2+11.59891*AT13^3)/1000000,3)-0 -> 0.298 | V13: =SUM(D13:U13) -> 98.697 | W13: =D13+H13+I13+J13+K13+L13+N13+M13 -> 54.891 | AB13: =B13 -> 6 | AC13: =C13 -> M | AD13: 214.08 | AE13: 61.7 | AF13: 150.04 | AG13: 152.05 | AH13: 328 | AI13: 162.1 | AJ13: 77.07 | AK13: 426.37 | AL13: =$AL$3+3.94 -> 26.68 | AM13: 129.63 | AN13: 110.02 | AO13: 338.1 | AP13: 539.5 | AQ13: 88.49 | AR13: 99.79 | AS13: 571.1 | AT13: 139.6 | AV13: 401.14 | AW13: 7.929 | AX13: 405 | AY13: 2.8 | AZ13: 397.8 | BA13: 2 | BB13: 359.5 | BC13: =(2261.87*BB13^2-1423337.72*BB13+223819398.05)/1000000 -> 4.454132 | BI13: 6 | BK13: =-4552010+77862.43*AD13-528.064*AD13^2+1.3857*AD13^3 -> 1511048.4 | BL13: =-3210651+145404.1*AE13-2052.163*AE13^2+14.3568*AE13^3 -> 1320621.8 | BM13: =IF(BK13<140,-737886.6-3612.887*AF13+84.47319*AF13^2,7040924-115283.7*AF13+485.2715*AF13^2) -> 668190.44 | BN13: =4001977-66502.13*AG13+275.558*AG13^2 -> 261009.34 | BO13: =12256870-84903.96*AH13+146.7551*AH13^2 -> 196871.8 | BP13: =9095248-135970.3*AI13+510.0572*AI13^2 -> 456934.48 | BQ13: =IF(BO13<73.2,-180.3+3.1*AJ13,312.46-10.83*AJ13+0.098*AJ13^2)*10000 -> 598908.2 | BR13: =(219.28*AK13^2-173172.2*AK13+34168761.89) -> 196544.1 | BS13: =5190570-498758.9*AL13+14528.53*AL13^2-112.5*AL13^3 -> 88880.707 | BT13: =(207.86-3.07416*AM13+0.00297*AM13^2+0.000073*AM13^3)*10000 -> 182798.19 | BU13: =(412.37-12.56*AN13+0.12278*AN13^2-0.000376*AN13^3)*10000 -> 159680.55 | BV13: =(5708324-41094.23*AO13+72.7745*AO13^2) -> 133335.1 | BW13: =(1307.749-5.30998*AP13+0.005386*AP13^2)*10000 -> 106652.97 | BX13: =(33.36079-1.57235*AQ13+0.020673*AQ13^2-0.000067*AQ13^3)*10000 -> 96774.683 | BY13: =(-106.619+3.872392*AR13-0.0491*AR13^2+0.000219*AR13^3)*10000 -> 84902.277 | BZ13: =(-2923.33+10.10447*AS13-0.00872*AS13^2)*10000 -> 32593.858 | CA13: =(149.6647-3.26844*AT13+0.02264*AT13^2-0.000048*AT13^3)*10000 -> 40161.559
B14: 7 | C14: T | D14: =ROUND(IF(AD14<205,SUM(-320030000,6636771*AD14,-46046*AD14^2,106.62*AD14^3),SUM(91660160,1216002*AD14,-22168*AD14^2,71.366*AD14^3))/1000000,3) -> 36.692 | E14: =ROUND((6669048.41-363409.186*AE14-307.876*AE14^2+152.3398*AE14^3)/1000000,3) -> 19.018 | F14: =ROUND((-98334930.2+3037042.21*AF14-30615.40767*AF14^2+101.23056*AF14^3)/1000000,3) -> 10.131 | G14: =AW14 -> 7.967 | H14: =ROUND((-174502023+4277428*AG14-35009.373*AG14^2+95.58911*AG14^3)/1000000-0.096,3) -> 2.586 | I14: =ROUND(IF(AH14<318,SUM(3.5242*AH14^2-2140.3*AH14+325031)/1000,SUM(70242780-813889.6*AH14+7928.716*AH14^2-35.20719*AH14^3+0.05082853*AH14^4)/1000000)-0.059,3) -> 2.191 | J14: =ROUND((-442650826+9751516.3*AI14-72042.8986*AI14^2+178.4049*AI14^3)/1000000,3)-0.071 -> 4.961 | K14: =ROUND(((4827852-139329.3*AJ14+2797.9*AJ14^2-98.98*AJ14^3+1.14*AJ14^4)/1000000),3)-0.05 -> 5.761 | L14: =ROUND((IF(AK14<424,SUM(5064.49*AK14^2-4133655.98*AK14+843517073.2),(7938.48*AK14^2-6579376.11*AK14+1363834719.7)))/1000000,3) -> 1.858 | M14: =ROUND((-8532018+1417757*AL14-72752.08*AL14^2+1191.92*AL14^3)/1000000,3) -> 0.143 | N14: =ROUND((-98293225+2791565*AM14-26671.1*AM14^2+85.56608*AM14^3)/1000000,3)-0 -> 1.819 | O14: =ROUND((-5101113+342273.3*AN14-5950.34*AN14^2+30.97425*AN14^3)/1000000,3)-0 -> 1.826 | P14: =ROUND((352562346-2208805*AO14+3459.655*AO14^2)/1000000,3)-0 -> 1.284 | Q14: =ROUND((426242189-1669663*AP14+1635.186*AP14^2)/1000000,3)+0.033 -> 1.43 | R14: =ROUND((2823894-25900.1*AQ14-1177.84*AQ14^2+13.979*AQ14^3)/1000000,3)-0.005 -> 0.99 | S14: =ROUND((-11518534+483790.5*AR14-6823.11*AR14^2+32.24883*AR14^3)/1000000,3)+0 -> 0.86 | T14: =ROUND((406066983-1465679*AS14+1322.517*AS14^2)/1000000,3)-0.001 -> 0.363 | U14: =ROUND((-13395930+388944*AT14-3702.68*AT14^2+11.59891*AT14^3)/1000000,3)-0 -> 0.298 | V14: =SUM(D14:U14) -> 100.178 | W14: =D14+H14+I14+J14+K14+L14+N14+M14 -> 56.011 | AB14: =B14 -> 7 | AC14: =C14 -> T | AD14: 214.39 | AE14: 61.82 | AF14: 150.15 | AG14: 152.68 | AH14: 328.15 | AI14: 162.3 | AJ14: 77.38 | AK14: 427.01 | AL14: =$AL$3+3.94 -> 26.68 | AM14: 129.8 | AN14: 110.31 | AO14: 338.4 | AP14: 539.5 | AQ14: 88.49 | AR14: 99.79 | AS14: 571.1 | AT14: 139.6 | AV14: 401.21 | AW14: 7.967 | AX14: 404.95 | AY14: 2.785 | AZ14: 397.8 | BA14: 2 | BB14: 359.5 | BC14: =(2261.87*BB14^2-1423337.72*BB14+223819398.05)/1000000 -> 4.454132 | BI14: 7 | BK14: =-4552010+77862.43*AD14-528.064*AD14^2+1.3857*AD14^3 -> 1524192.4 | BL14: =-3210651+145404.1*AE14-2052.163*AE14^2+14.3568*AE14^3 -> 1327366.3 | BM14: =IF(BK14<140,-737886.6-3612.887*AF14+84.47319*AF14^2,7040924-115283.7*AF14+485.2715*AF14^2) -> 671533.33 | BN14: =4001977-66502.13*AG14+275.558*AG14^2 -> 272014.59 | BO14: =12256870-84903.96*AH14+146.7551*AH14^2 -> 198580.21 | BP14: =9095248-135970.3*AI14+510.0572*AI14^2 -> 462832.93 | BQ14: =IF(BO14<73.2,-180.3+3.1*AJ14,312.46-10.83*AJ14+0.098*AJ14^2)*10000 -> 612257.11 | BR14: =(219.28*AK14^2-173172.2*AK14+34168761.89) -> 205476.56 | BS14: =5190570-498758.9*AL14+14528.53*AL14^2-112.5*AL14^3 -> 88880.707 | BT14: =(207.86-3.07416*AM14+0.00297*AM14^2+0.000073*AM14^3)*10000 -> 185146.29 | BU14: =(412.37-12.56*AN14+0.12278*AN14^2-0.000376*AN14^3)*10000 -> 162007.32 | BV14: =(5708324-41094.23*AO14+72.7745*AO14^2) -> 135776.41 | BW14: =(1307.749-5.30998*AP14+0.005386*AP14^2)*10000 -> 106652.97 | BX14: =(33.36079-1.57235*AQ14+0.020673*AQ14^2-0.000067*AQ14^3)*10000 -> 96774.683 | BY14: =(-106.619+3.872392*AR14-0.0491*AR14^2+0.000219*AR14^3)*10000 -> 84902.277 | BZ14: =(-2923.33+10.10447*AS14-0.00872*AS14^2)*10000 -> 32593.858 | CA14: =(149.6647-3.26844*AT14+0.02264*AT14^2-0.000048*AT14^3)*10000 -> 40161.559
B15: 8 | C15: W | D15: =ROUND(IF(AD15<205,SUM(-320030000,6636771*AD15,-46046*AD15^2,106.62*AD15^3),SUM(91660160,1216002*AD15,-22168*AD15^2,71.366*AD15^3))/1000000,3) -> 37.144 | E15: =ROUND((6669048.41-363409.186*AE15-307.876*AE15^2+152.3398*AE15^3)/1000000,3) -> 19.153 | F15: =ROUND((-98334930.2+3037042.21*AF15-30615.40767*AF15^2+101.23056*AF15^3)/1000000,3) -> 10.2 | G15: =AW15 -> 8.011 | H15: =ROUND((-174502023+4277428*AG15-35009.373*AG15^2+95.58911*AG15^3)/1000000-0.096,3) -> 2.73 | I15: =ROUND(IF(AH15<318,SUM(3.5242*AH15^2-2140.3*AH15+325031)/1000,SUM(70242780-813889.6*AH15+7928.716*AH15^2-35.20719*AH15^3+0.05082853*AH15^4)/1000000)-0.059,3) -> 2.217 | J15: =ROUND((-442650826+9751516.3*AI15-72042.8986*AI15^2+178.4049*AI15^3)/1000000,3)-0.071 -> 5.046 | K15: =ROUND(((4827852-139329.3*AJ15+2797.9*AJ15^2-98.98*AJ15^3+1.14*AJ15^4)/1000000),3)-0.05 -> 5.951 | L15: =ROUND((IF(AK15<424,SUM(5064.49*AK15^2-4133655.98*AK15+843517073.2),(7938.48*AK15^2-6579376.11*AK15+1363834719.7)))/1000000,3) -> 1.979 | M15: =ROUND((-8532018+1417757*AL15-72752.08*AL15^2+1191.92*AL15^3)/1000000,3) -> 0.147 | N15: =ROUND((-98293225+2791565*AM15-26671.1*AM15^2+85.56608*AM15^3)/1000000,3)-0 -> 1.834 | O15: =ROUND((-5101113+342273.3*AN15-5950.34*AN15^2+30.97425*AN15^3)/1000000,3)-0 -> 1.858 | P15: =ROUND((352562346-2208805*AO15+3459.655*AO15^2)/1000000,3)-0 -> 1.317 | Q15: =ROUND((426242189-1669663*AP15+1635.186*AP15^2)/1000000,3)+0.033 -> 1.43 | R15: =ROUND((2823894-25900.1*AQ15-1177.84*AQ15^2+13.979*AQ15^3)/1000000,3)-0.005 -> 0.99 | S15: =ROUND((-11518534+483790.5*AR15-6823.11*AR15^2+32.24883*AR15^3)/1000000,3)+0 -> 0.86 | T15: =ROUND((406066983-1465679*AS15+1322.517*AS15^2)/1000000,3)-0.001 -> 0.363 | U15: =ROUND((-13395930+388944*AT15-3702.68*AT15^2+11.59891*AT15^3)/1000000,3)-0 -> 0.298 | V15: =SUM(D15:U15) -> 101.528 | W15: =D15+H15+I15+J15+K15+L15+N15+M15 -> 57.048 | AB15: =B15 -> 8 | AC15: =C15 -> W | AD15: 214.68 | AE15: 61.92 | AF15: 150.25 | AG15: 153.2 | AH15: 328.28 | AI15: 162.48 | AJ15: 77.68 | AK15: 427.6 | AL15: =$AL$3+3.98 -> 26.72 | AM15: 129.88 | AN15: 110.51 | AO15: 338.65 | AP15: 539.5 | AQ15: 88.49 | AR15: 99.79 | AS15: 571.1 | AT15: 139.6 | AV15: 401.29 | AW15: 8.011 | AX15: 404.9 | AY15: 2.77 | AZ15: 397.8 | BA15: 2 | BB15: 359.5 | BC15: =(2261.87*BB15^2-1423337.72*BB15+223819398.05)/1000000 -> 4.454132 | BI15: 8 | BK15: =-4552010+77862.43*AD15-528.064*AD15^2+1.3857*AD15^3 -> 1536551.5 | BL15: =-3210651+145404.1*AE15-2052.163*AE15^2+14.3568*AE15^3 -> 1333000.1 | BM15: =IF(BK15<140,-737886.6-3612.887*AF15+84.47319*AF15^2,7040924-115283.7*AF15+485.2715*AF15^2) -> 674582.52 | BN15: =4001977-66502.13*AG15+275.558*AG15^2 -> 281263.08 | BO15: =12256870-84903.96*AH15+146.7551*AH15^2 -> 200066.17 | BP15: =9095248-135970.3*AI15+510.0572*AI15^2 -> 468176.43 | BQ15: =IF(BO15<73.2,-180.3+3.1*AJ15,312.46-10.83*AJ15+0.098*AJ15^2)*10000 -> 625354.75 | BR15: =(219.28*AK15^2-173172.2*AK15+34168761.89) -> 213870.3 | BS15: =5190570-498758.9*AL15+14528.53*AL15^2-112.5*AL15^3 -> 90339.275 | BT15: =(207.86-3.07416*AM15+0.00297*AM15^2+0.000073*AM15^3)*10000 -> 186257.56 | BU15: =(412.37-12.56*AN15+0.12278*AN15^2-0.000376*AN15^3)*10000 -> 163610.4 | BV15: =(5708324-41094.23*AO15+72.7745*AO15^2) -> 137820.85 | BW15: =(1307.749-5.30998*AP15+0.005386*AP15^2)*10000 -> 106652.97 | BX15: =(33.36079-1.57235*AQ15+0.020673*AQ15^2-0.000067*AQ15^3)*10000 -> 96774.683 | BY15: =(-106.619+3.872392*AR15-0.0491*AR15^2+0.000219*AR15^3)*10000 -> 84902.277 | BZ15: =(-2923.33+10.10447*AS15-0.00872*AS15^2)*10000 -> 32593.858 | CA15: =(149.6647-3.26844*AT15+0.02264*AT15^2-0.000048*AT15^3)*10000 -> 40161.559
B16: 9 | C16: T | D16: =ROUND(IF(AD16<205,SUM(-320030000,6636771*AD16,-46046*AD16^2,106.62*AD16^3),SUM(91660160,1216002*AD16,-22168*AD16^2,71.366*AD16^3))/1000000,3) -> 37.505 | E16: =ROUND((6669048.41-363409.186*AE16-307.876*AE16^2+152.3398*AE16^3)/1000000,3) -> 19.275 | F16: =ROUND((-98334930.2+3037042.21*AF16-30615.40767*AF16^2+101.23056*AF16^3)/1000000,3) -> 10.277 | G16: =AW16 -> 8.049 | H16: =ROUND((-174502023+4277428*AG16-35009.373*AG16^2+95.58911*AG16^3)/1000000-0.096,3) -> 2.8 | I16: =ROUND(IF(AH16<318,SUM(3.5242*AH16^2-2140.3*AH16+325031)/1000,SUM(70242780-813889.6*AH16+7928.716*AH16^2-35.20719*AH16^3+0.05082853*AH16^4)/1000000)-0.059,3) -> 2.241 | J16: =ROUND((-442650826+9751516.3*AI16-72042.8986*AI16^2+178.4049*AI16^3)/1000000,3)-0.071 -> 5.126 | K16: =ROUND(((4827852-139329.3*AJ16+2797.9*AJ16^2-98.98*AJ16^3+1.14*AJ16^4)/1000000),3)-0.05 -> 6.087 | L16: =ROUND((IF(AK16<424,SUM(5064.49*AK16^2-4133655.98*AK16+843517073.2),(7938.48*AK16^2-6579376.11*AK16+1363834719.7)))/1000000,3) -> 2.066 | M16: =ROUND((-8532018+1417757*AL16-72752.08*AL16^2+1191.92*AL16^3)/1000000,3) -> 0.147 | N16: =ROUND((-98293225+2791565*AM16-26671.1*AM16^2+85.56608*AM16^3)/1000000,3)-0 -> 1.846 | O16: =ROUND((-5101113+342273.3*AN16-5950.34*AN16^2+30.97425*AN16^3)/1000000,3)-0 -> 1.871 | P16: =ROUND((352562346-2208805*AO16+3459.655*AO16^2)/1000000,3)-0 -> 1.351 | Q16: =ROUND((426242189-1669663*AP16+1635.186*AP16^2)/1000000,3)+0.033 -> 1.43 | R16: =ROUND((2823894-25900.1*AQ16-1177.84*AQ16^2+13.979*AQ16^3)/1000000,3)-0.005 -> 0.99 | S16: =ROUND((-11518534+483790.5*AR16-6823.11*AR16^2+32.24883*AR16^3)/1000000,3)+0 -> 0.86 | T16: =ROUND((406066983-1465679*AS16+1322.517*AS16^2)/1000000,3)-0.001 -> 0.363 | U16: =ROUND((-13395930+388944*AT16-3702.68*AT16^2+11.59891*AT16^3)/1000000,3)-0 -> 0.298 | V16: =SUM(D16:U16) -> 102.582 | W16: =D16+H16+I16+J16+K16+L16+N16+M16 -> 57.818 | AB16: =B16 -> 9 | AC16: =C16 -> T | AD16: 214.91 | AE16: 62.01 | AF16: 150.36 | AG16: 153.45 | AH16: 328.4 | AI16: 162.65 | AJ16: 77.89 | AK16: 428.01 | AL16: =$AL$3+3.98 -> 26.72 | AM16: 129.94 | AN16: 110.59 | AO16: 338.9 | AP16: 539.5 | AQ16: 88.49 | AR16: 99.79 | AS16: 571.1 | AT16: 139.6 | AV16: 401.36 | AW16: 8.049 | AX16: 404.6 | AY16: 2.68 | AZ16: 397.8 | BA16: 2 | BB16: 359.5 | BC16: =(2261.87*BB16^2-1423337.72*BB16+223819398.05)/1000000 -> 4.454132 | BI16: 9 | BK16: =-4552010+77862.43*AD16-528.064*AD16^2+1.3857*AD16^3 -> 1546397.1 | BL16: =-3210651+145404.1*AE16-2052.163*AE16^2+14.3568*AE16^3 -> 1338081.1 | BM16: =IF(BK16<140,-737886.6-3612.887*AF16+84.47319*AF16^2,7040924-115283.7*AF16+485.2715*AF16^2) -> 677947.83 | BN16: =4001977-66502.13*AG16+275.558*AG16^2 -> 285762.51 | BO16: =12256870-84903.96*AH16+146.7551*AH16^2 -> 201442.23 | BP16: =9095248-135970.3*AI16+510.0572*AI16^2 -> 473253.41 | BQ16: =IF(BO16<73.2,-180.3+3.1*AJ16,312.46-10.83*AJ16+0.098*AJ16^2)*10000 -> 634628.06 | BR16: =(219.28*AK16^2-173172.2*AK16+34168761.89) -> 219793.15 | BS16: =5190570-498758.9*AL16+14528.53*AL16^2-112.5*AL16^3 -> 90339.275 | BT16: =(207.86-3.07416*AM16+0.00297*AM16^2+0.000073*AM16^3)*10000 -> 187093.65 | BU16: =(412.37-12.56*AN16+0.12278*AN16^2-0.000376*AN16^3)*10000 -> 164251.22 | BV16: =(5708324-41094.23*AO16+72.7745*AO16^2) -> 139874.38 | BW16: =(1307.749-5.30998*AP16+0.005386*AP16^2)*10000 -> 106652.97 | BX16: =(33.36079-1.57235*AQ16+0.020673*AQ16^2-0.000067*AQ16^3)*10000 -> 96774.683 | BY16: =(-106.619+3.872392*AR16-0.0491*AR16^2+0.000219*AR16^3)*10000 -> 84902.277 | BZ16: =(-2923.33+10.10447*AS16-0.00872*AS16^2)*10000 -> 32593.858 | CA16: =(149.6647-3.26844*AT16+0.02264*AT16^2-0.000048*AT16^3)*10000 -> 40161.559
B17: 10 | C17: F | AB17: =B17 -> 10 | AC17: =C17 -> F | BI17: 10 | BK17: =-4552010+77862.43*AD17-528.064*AD17^2+1.3857*AD17^3 -> -4552010 | BL17: =-3210651+145404.1*AE17-2052.163*AE17^2+14.3568*AE17^3 -> -3210651 | BM17: =IF(BK17<140,-737886.6-3612.887*AF17+84.47319*AF17^2,7040924-115283.7*AF17+485.2715*AF17^2) -> -737886.6 | BN17: =4001977-66502.13*AG17+275.558*AG17^2 -> 4001977 | BO17: =12256870-84903.96*AH17+146.7551*AH17^2 -> 12256870 | BP17: =9095248-135970.3*AI17+510.0572*AI17^2 -> 9095248 | BQ17: =IF(BO17<73.2,-180.3+3.1*AJ17,312.46-10.83*AJ17+0.098*AJ17^2)*10000 -> 3124600 | BR17: =(219.28*AK17^2-173172.2*AK17+34168761.89) -> 34168762 | BS17: =5190570-498758.9*AL17+14528.53*AL17^2-112.5*AL17^3 -> 5190570 | BT17: =(207.86-3.07416*AM17+0.00297*AM17^2+0.000073*AM17^3)*10000 -> 2078600 | BU17: =(412.37-12.56*AN17+0.12278*AN17^2-0.000376*AN17^3)*10000 -> 4123700 | BV17: =(5708324-41094.23*AO17+72.7745*AO17^2) -> 5708324 | BW17: =(1307.749-5.30998*AP17+0.005386*AP17^2)*10000 -> 13077490 | BX17: =(33.36079-1.57235*AQ17+0.020673*AQ17^2-0.000067*AQ17^3)*10000 -> 333607.9 | BY17: =(-106.619+3.872392*AR17-0.0491*AR17^2+0.000219*AR17^3)*10000 -> -1066190 | BZ17: =(-2923.33+10.10447*AS17-0.00872*AS17^2)*10000 -> -29233300 | CA17: =(149.6647-3.26844*AT17+0.02264*AT17^2-0.000048*AT17^3)*10000 -> 1496647
B18: 11 | C18: S | AB18: =B18 -> 11 | AC18: =C18 -> S | BI18: 11 | BK18: =-4552010+77862.43*AD18-528.064*AD18^2+1.3857*AD18^3 -> -4552010 | BL18: =-3210651+145404.1*AE18-2052.163*AE18^2+14.3568*AE18^3 -> -3210651 | BM18: =IF(BK18<140,-737886.6-3612.887*AF18+84.47319*AF18^2,7040924-115283.7*AF18+485.2715*AF18^2) -> -737886.6 | BN18: =4001977-66502.13*AG18+275.558*AG18^2 -> 4001977 | BO18: =12256870-84903.96*AH18+146.7551*AH18^2 -> 12256870 | BP18: =9095248-135970.3*AI18+510.0572*AI18^2 -> 9095248 | BQ18: =IF(BO18<73.2,-180.3+3.1*AJ18,312.46-10.83*AJ18+0.098*AJ18^2)*10000 -> 3124600 | BR18: =(219.28*AK18^2-173172.2*AK18+34168761.89) -> 34168762 | BS18: =5190570-498758.9*AL18+14528.53*AL18^2-112.5*AL18^3 -> 5190570 | BT18: =(207.86-3.07416*AM18+0.00297*AM18^2+0.000073*AM18^3)*10000 -> 2078600 | BU18: =(412.37-12.56*AN18+0.12278*AN18^2-0.000376*AN18^3)*10000 -> 4123700 | BV18: =(5708324-41094.23*AO18+72.7745*AO18^2) -> 5708324 | BW18: =(1307.749-5.30998*AP18+0.005386*AP18^2)*10000 -> 13077490 | BX18: =(33.36079-1.57235*AQ18+0.020673*AQ18^2-0.000067*AQ18^3)*10000 -> 333607.9 | BY18: =(-106.619+3.872392*AR18-0.0491*AR18^2+0.000219*AR18^3)*10000 -> -1066190 | BZ18: =(-2923.33+10.10447*AS18-0.00872*AS18^2)*10000 -> -29233300 | CA18: =(149.6647-3.26844*AT18+0.02264*AT18^2-0.000048*AT18^3)*10000 -> 1496647
B19: 12 | C19: S | AB19: =B19 -> 12 | AC19: =C19 -> S | BI19: 12 | BK19: =-4552010+77862.43*AD19-528.064*AD19^2+1.3857*AD19^3 -> -4552010 | BL19: =-3210651+145404.1*AE19-2052.163*AE19^2+14.3568*AE19^3 -> -3210651 | BM19: =IF(BK19<140,-737886.6-3612.887*AF19+84.47319*AF19^2,7040924-115283.7*AF19+485.2715*AF19^2) -> -737886.6 | BN19: =4001977-66502.13*AG19+275.558*AG19^2 -> 4001977 | BO19: =12256870-84903.96*AH19+146.7551*AH19^2 -> 12256870 | BP19: =9095248-135970.3*AI19+510.0572*AI19^2 -> 9095248 | BQ19: =IF(BO19<73.2,-180.3+3.1*AJ19,312.46-10.83*AJ19+0.098*AJ19^2)*10000 -> 3124600 | BR19: =(219.28*AK19^2-173172.2*AK19+34168761.89) -> 34168762 | BS19: =5190570-498758.9*AL19+14528.53*AL19^2-112.5*AL19^3 -> 5190570 | BT19: =(207.86-3.07416*AM19+0.00297*AM19^2+0.000073*AM19^3)*10000 -> 2078600 | BU19: =(412.37-12.56*AN19+0.12278*AN19^2-0.000376*AN19^3)*10000 -> 4123700 | BV19: =(5708324-41094.23*AO19+72.7745*AO19^2) -> 5708324 | BW19: =(1307.749-5.30998*AP19+0.005386*AP19^2)*10000 -> 13077490 | BX19: =(33.36079-1.57235*AQ19+0.020673*AQ19^2-0.000067*AQ19^3)*10000 -> 333607.9 | BY19: =(-106.619+3.872392*AR19-0.0491*AR19^2+0.000219*AR19^3)*10000 -> -1066190 | BZ19: =(-2923.33+10.10447*AS19-0.00872*AS19^2)*10000 -> -29233300 | CA19: =(149.6647-3.26844*AT19+0.02264*AT19^2-0.000048*AT19^3)*10000 -> 1496647
B20: 13 | C20: M | AB20: =B20 -> 13 | AC20: =C20 -> M | BI20: 13 | BK20: =-4552010+77862.43*AD20-528.064*AD20^2+1.3857*AD20^3 -> -4552010 | BL20: =-3210651+145404.1*AE20-2052.163*AE20^2+14.3568*AE20^3 -> -3210651 | BM20: =IF(BK20<140,-737886.6-3612.887*AF20+84.47319*AF20^2,7040924-115283.7*AF20+485.2715*AF20^2) -> -737886.6 | BN20: =4001977-66502.13*AG20+275.558*AG20^2 -> 4001977 | BO20: =12256870-84903.96*AH20+146.7551*AH20^2 -> 12256870 | BP20: =9095248-135970.3*AI20+510.0572*AI20^2 -> 9095248 | BQ20: =IF(BO20<73.2,-180.3+3.1*AJ20,312.46-10.83*AJ20+0.098*AJ20^2)*10000 -> 3124600 | BR20: =(219.28*AK20^2-173172.2*AK20+34168761.89) -> 34168762 | BS20: =5190570-498758.9*AL20+14528.53*AL20^2-112.5*AL20^3 -> 5190570 | BT20: =(207.86-3.07416*AM20+0.00297*AM20^2+0.000073*AM20^3)*10000 -> 2078600 | BU20: =(412.37-12.56*AN20+0.12278*AN20^2-0.000376*AN20^3)*10000 -> 4123700 | BV20: =(5708324-41094.23*AO20+72.7745*AO20^2) -> 5708324 | BW20: =(1307.749-5.30998*AP20+0.005386*AP20^2)*10000 -> 13077490 | BX20: =(33.36079-1.57235*AQ20+0.020673*AQ20^2-0.000067*AQ20^3)*10000 -> 333607.9 | BY20: =(-106.619+3.872392*AR20-0.0491*AR20^2+0.000219*AR20^3)*10000 -> -1066190 | BZ20: =(-2923.33+10.10447*AS20-0.00872*AS20^2)*10000 -> -29233300 | CA20: =(149.6647-3.26844*AT20+0.02264*AT20^2-0.000048*AT20^3)*10000 -> 1496647
B21: 14 | C21: T | D21: =ROUND(IF(AD21<205,SUM(-320030000,6636771*AD21,-46046*AD21^2,106.62*AD21^3),SUM(91660160,1216002*AD21,-22168*AD21^2,71.366*AD21^3))/1000000,3) -> 39.072 | E21: =ROUND((6669048.41-363409.186*AE21-307.876*AE21^2+152.3398*AE21^3)/1000000,3) -> 19.725 | F21: =ROUND((-98334930.2+3037042.21*AF21-30615.40767*AF21^2+101.23056*AF21^3)/1000000,3) -> 10.501 | G21: =AW21 -> 8.197 | H21: =ROUND((-174502023+4277428*AG21-35009.373*AG21^2+95.58911*AG21^3)/1000000-0.096,3) -> 3.156 | I21: =ROUND(IF(AH21<318,SUM(3.5242*AH21^2-2140.3*AH21+325031)/1000,SUM(70242780-813889.6*AH21+7928.716*AH21^2-35.20719*AH21^3+0.05082853*AH21^4)/1000000)-0.059,3) -> 2.334 | J21: =ROUND((-442650826+9751516.3*AI21-72042.8986*AI21^2+178.4049*AI21^3)/1000000,3)-0.071 -> 5.441 | K21: =ROUND(((4827852-139329.3*AJ21+2797.9*AJ21^2-98.98*AJ21^3+1.14*AJ21^4)/1000000),3)-0.05 -> 6.579 | L21: =ROUND((IF(AK21<424,SUM(5064.49*AK21^2-4133655.98*AK21+843517073.2),(7938.48*AK21^2-6579376.11*AK21+1363834719.7)))/1000000,3) -> 2.192 | M21: =ROUND((-8532018+1417757*AL21-72752.08*AL21^2+1191.92*AL21^3)/1000000,3) -> 0.149 | N21: =ROUND((-98293225+2791565*AM21-26671.1*AM21^2+85.56608*AM21^3)/1000000,3)-0.001 -> 1.886 | O21: =ROUND((-5101113+342273.3*AN21-5950.34*AN21^2+30.97425*AN21^3)/1000000,3)-0 -> 1.915 | P21: =ROUND((352562346-2208805*AO21+3459.655*AO21^2)/1000000,3)-0 -> 1.483 | Q21: =ROUND((426242189-1669663*AP21+1635.186*AP21^2)/1000000,3)+0.033 -> 1.43 | R21: =ROUND((2823894-25900.1*AQ21-1177.84*AQ21^2+13.979*AQ21^3)/1000000,3)-0.005 -> 0.99 | S21: =ROUND((-11518534+483790.5*AR21-6823.11*AR21^2+32.24883*AR21^3)/1000000,3)+0 -> 0.86 | T21: =ROUND((406066983-1465679*AS21+1322.517*AS21^2)/1000000,3)-0.001 -> 0.363 | U21: =ROUND((-13395930+388944*AT21-3702.68*AT21^2+11.59891*AT21^3)/1000000,3)-0 -> 0.298 | V21: =SUM(D21:U21) -> 106.571 | W21: =D21+H21+I21+J21+K21+L21+N21+M21 -> 60.809 | AB21: =B21 -> 14 | AC21: =C21 -> T | AD21: 215.89 | AE21: 62.34 | AF21: 150.68 | AG21: 154.65 | AH21: 328.85 | AI21: 163.3 | AJ21: 78.63 | AK21: 428.58 | AL21: =$AL$3+4.01 -> 26.75 | AM21: 130.15 | AN21: 110.86 | AO21: 339.85 | AP21: 539.5 | AQ21: 88.49 | AR21: 99.79 | AS21: 571.1 | AT21: 139.6 | AV21: 401.63 | AW21: 8.197 | AX21: 404.97 | AY21: 2.79 | AZ21: 397.8 | BA21: 2 | BB21: 359.5 | BC21: =(2261.87*BB21^2-1423337.72*BB21+223819398.05)/1000000 -> 4.454132 | BI21: 14 | BK21: =-4552010+77862.43*AD21-528.064*AD21^2+1.3857*AD21^3 -> 1588782.5 | BL21: =-3210651+145404.1*AE21-2052.163*AE21^2+14.3568*AE21^3 -> 1356797.6 | BM21: =IF(BK21<140,-737886.6-3612.887*AF21+84.47319*AF21^2,7040924-115283.7*AF21+485.2715*AF21^2) -> 687804.61 | BN21: =4001977-66502.13*AG21+275.558*AG21^2 -> 307839.26 | BO21: =12256870-84903.96*AH21+146.7551*AH21^2 -> 206640.11 | BP21: =9095248-135970.3*AI21+510.0572*AI21^2 -> 492937.26 | BQ21: =IF(BO21<73.2,-180.3+3.1*AJ21,312.46-10.83*AJ21+0.098*AJ21^2)*10000 -> 667994.36 | BR21: =(219.28*AK21^2-173172.2*AK21+34168761.89) -> 228149.83 | BS21: =5190570-498758.9*AL21+14528.53*AL21^2-112.5*AL21^3 -> 91444.775 | BT21: =(207.86-3.07416*AM21+0.00297*AM21^2+0.000073*AM21^3)*10000 -> 190037.79 | BU21: =(412.37-12.56*AN21+0.12278*AN21^2-0.000376*AN21^3)*10000 -> 166412.07 | BV21: =(5708324-41094.23*AO21+72.7745*AO21^2) -> 147760.77 | BW21: =(1307.749-5.30998*AP21+0.005386*AP21^2)*10000 -> 106652.97 | BX21: =(33.36079-1.57235*AQ21+0.020673*AQ21^2-0.000067*AQ21^3)*10000 -> 96774.683 | BY21: =(-106.619+3.872392*AR21-0.0491*AR21^2+0.000219*AR21^3)*10000 -> 84902.277 | BZ21: =(-2923.33+10.10447*AS21-0.00872*AS21^2)*10000 -> 32593.858 | CA21: =(149.6647-3.26844*AT21+0.02264*AT21^2-0.000048*AT21^3)*10000 -> 40161.559
B22: 15 | C22: W | D22: =ROUND(IF(AD22<205,SUM(-320030000,6636771*AD22,-46046*AD22^2,106.62*AD22^3),SUM(91660160,1216002*AD22,-22168*AD22^2,71.366*AD22^3))/1000000,3) -> 39.333 | E22: =ROUND((6669048.41-363409.186*AE22-307.876*AE22^2+152.3398*AE22^3)/1000000,3) -> 19.78 | F22: =ROUND((-98334930.2+3037042.21*AF22-30615.40767*AF22^2+101.23056*AF22^3)/1000000,3) -> 10.55 | G22: =AW22 -> 8.219 | H22: =ROUND((-174502023+4277428*AG22-35009.373*AG22^2+95.58911*AG22^3)/1000000-0.096,3) -> 3.196 | I22: =ROUND(IF(AH22<318,SUM(3.5242*AH22^2-2140.3*AH22+325031)/1000,SUM(70242780-813889.6*AH22+7928.716*AH22^2-35.20719*AH22^3+0.05082853*AH22^4)/1000000)-0.059,3) -> 2.349 | J22: =ROUND((-442650826+9751516.3*AI22-72042.8986*AI22^2+178.4049*AI22^3)/1000000,3)-0.071 -> 5.481 | K22: =ROUND(((4827852-139329.3*AJ22+2797.9*AJ22^2-98.98*AJ22^3+1.14*AJ22^4)/1000000),3)-0.05 -> 6.655 | L22: =ROUND((IF(AK22<424,SUM(5064.49*AK22^2-4133655.98*AK22+843517073.2),(7938.48*AK22^2-6579376.11*AK22+1363834719.7)))/1000000,3) -> 2.181 | M22: =ROUND((-8532018+1417757*AL22-72752.08*AL22^2+1191.92*AL22^3)/1000000,3) -> 0.149 | N22: =ROUND((-98293225+2791565*AM22-26671.1*AM22^2+85.56608*AM22^3)/1000000,3)-0.001 -> 1.888 | O22: =ROUND((-5101113+342273.3*AN22-5950.34*AN22^2+30.97425*AN22^3)/1000000,3)-0 -> 1.932 | P22: =ROUND((352562346-2208805*AO22+3459.655*AO22^2)/1000000,3)-0 -> 1.505 | Q22: =ROUND((426242189-1669663*AP22+1635.186*AP22^2)/1000000,3)+0.033 -> 1.43 | R22: =ROUND((2823894-25900.1*AQ22-1177.84*AQ22^2+13.979*AQ22^3)/1000000,3)-0.005 -> 0.99 | S22: =ROUND((-11518534+483790.5*AR22-6823.11*AR22^2+32.24883*AR22^3)/1000000,3)+0 -> 0.86 | T22: =ROUND((406066983-1465679*AS22+1322.517*AS22^2)/1000000,3)-0.001 -> 0.363 | U22: =ROUND((-13395930+388944*AT22-3702.68*AT22^2+11.59891*AT22^3)/1000000,3)-0 -> 0.298 | V22: =SUM(D22:U22) -> 107.159 | W22: =D22+H22+I22+J22+K22+L22+N22+M22 -> 61.232 | AB22: =B22 -> 15 | AC22: =C22 -> W | AD22: 216.05 | AE22: 62.38 | AF22: 150.75 | AG22: 154.78 | AH22: 328.92 | AI22: 163.38 | AJ22: 78.74 | AK22: 428.53 | AL22: =$AL$3+4.01 -> 26.75 | AM22: 130.16 | AN22: 110.96 | AO22: 340 | AP22: 539.5 | AQ22: 88.49 | AR22: 99.79 | AS22: 571.1 | AT22: 139.6 | AV22: 401.67 | AW22: 8.219 | AX22: 404.98 | AY22: 2.794 | AZ22: 397.8 | BA22: 2 | BB22: 359.5 | BC22: =(2261.87*BB22^2-1423337.72*BB22+223819398.05)/1000000 -> 4.454132 | BI22: 15 | BK22: =-4552010+77862.43*AD22-528.064*AD22^2+1.3857*AD22^3 -> 1595769.8 | BL22: =-3210651+145404.1*AE22-2052.163*AE22^2+14.3568*AE22^3 -> 1359075.5 | BM22: =IF(BK22<140,-737886.6-3612.887*AF22+84.47319*AF22^2,7040924-115283.7*AF22+485.2715*AF22^2) -> 689974.03 | BN22: =4001977-66502.13*AG22+275.558*AG22^2 -> 310278.55 | BO22: =12256870-84903.96*AH22+146.7551*AH22^2 -> 207454.01 | BP22: =9095248-135970.3*AI22+510.0572*AI22^2 -> 495389.67 | BQ22: =IF(BO22<73.2,-180.3+3.1*AJ22,312.46-10.83*AJ22+0.098*AJ22^2)*10000 -> 673045.85 | BR22: =(219.28*AK22^2-173172.2*AK22+34168761.89) -> 227411.09 | BS22: =5190570-498758.9*AL22+14528.53*AL22^2-112.5*AL22^3 -> 91444.775 | BT22: =(207.86-3.07416*AM22+0.00297*AM22^2+0.000073*AM22^3)*10000 -> 190178.68 | BU22: =(412.37-12.56*AN22+0.12278*AN22^2-0.000376*AN22^3)*10000 -> 167211.57 | BV22: =(5708324-41094.23*AO22+72.7745*AO22^2) -> 149018 | BW22: =(1307.749-5.30998*AP22+0.005386*AP22^2)*10000 -> 106652.97 | BX22: =(33.36079-1.57235*AQ22+0.020673*AQ22^2-0.000067*AQ22^3)*10000 -> 96774.683 | BY22: =(-106.619+3.872392*AR22-0.0491*AR22^2+0.000219*AR22^3)*10000 -> 84902.277 | BZ22: =(-2923.33+10.10447*AS22-0.00872*AS22^2)*10000 -> 32593.858 | CA22: =(149.6647-3.26844*AT22+0.02264*AT22^2-0.000048*AT22^3)*10000 -> 40161.559
B23: 16 | C23: T | D23: =ROUND(IF(AD23<205,SUM(-320030000,6636771*AD23,-46046*AD23^2,106.62*AD23^3),SUM(91660160,1216002*AD23,-22168*AD23^2,71.366*AD23^3))/1000000,3) -> 39.545 | E23: =ROUND((6669048.41-363409.186*AE23-307.876*AE23^2+152.3398*AE23^3)/1000000,3) -> 19.849 | F23: =ROUND((-98334930.2+3037042.21*AF23-30615.40767*AF23^2+101.23056*AF23^3)/1000000,3) -> 10.593 | G23: =AW23 -> 8.235 | H23: =ROUND((-174502023+4277428*AG23-35009.373*AG23^2+95.58911*AG23^3)/1000000-0.096,3) -> 3.249 | I23: =ROUND(IF(AH23<318,SUM(3.5242*AH23^2-2140.3*AH23+325031)/1000,SUM(70242780-813889.6*AH23+7928.716*AH23^2-35.20719*AH23^3+0.05082853*AH23^4)/1000000)-0.059,3) -> 2.366 | J23: =ROUND((-442650826+9751516.3*AI23-72042.8986*AI23^2+178.4049*AI23^3)/1000000,3)-0.071 -> 5.521 | K23: =ROUND(((4827852-139329.3*AJ23+2797.9*AJ23^2-98.98*AJ23^3+1.14*AJ23^4)/1000000),3)-0.05 -> 6.73 | L23: =ROUND((IF(AK23<424,SUM(5064.49*AK23^2-4133655.98*AK23+843517073.2),(7938.48*AK23^2-6579376.11*AK23+1363834719.7)))/1000000,3) -> 2.156 | M23: =ROUND((-8532018+1417757*AL23-72752.08*AL23^2+1191.92*AL23^3)/1000000,3) -> 0.149 | N23: =ROUND((-98293225+2791565*AM23-26671.1*AM23^2+85.56608*AM23^3)/1000000,3)-0.001 -> 1.896 | O23: =ROUND((-5101113+342273.3*AN23-5950.34*AN23^2+30.97425*AN23^3)/1000000,3)-0 -> 1.952 | P23: =ROUND((352562346-2208805*AO23+3459.655*AO23^2)/1000000,3)-0 -> 1.526 | Q23: =ROUND((426242189-1669663*AP23+1635.186*AP23^2)/1000000,3)+0.033 -> 1.43 | R23: =ROUND((2823894-25900.1*AQ23-1177.84*AQ23^2+13.979*AQ23^3)/1000000,3)-0.005 -> 0.99 | S23: =ROUND((-11518534+483790.5*AR23-6823.11*AR23^2+32.24883*AR23^3)/1000000,3)+0 -> 0.86 | T23: =ROUND((406066983-1465679*AS23+1322.517*AS23^2)/1000000,3)-0.001 -> 0.363 | U23: =ROUND((-13395930+388944*AT23-3702.68*AT23^2+11.59891*AT23^3)/1000000,3)-0 -> 0.298 | V23: =SUM(D23:U23) -> 107.708 | W23: =D23+H23+I23+J23+K23+L23+N23+M23 -> 61.612 | AB23: =B23 -> 16 | AC23: =C23 -> T | AD23: 216.18 | AE23: 62.43 | AF23: 150.81 | AG23: 154.95 | AH23: 329 | AI23: 163.46 | AJ23: 78.85 | AK23: 428.42 | AL23: =$AL$3+4.01 -> 26.75 | AM23: 130.2 | AN23: 111.08 | AO23: 340.15 | AP23: 539.5 | AQ23: 88.49 | AR23: 99.79 | AS23: 571.1 | AT23: 139.6 | AV23: 401.7 | AW23: 8.235 | AX23: 404.98 | AY23: 2.794 | AZ23: 397.8 | BA23: 2 | BB23: 359.5 | BC23: =(2261.87*BB23^2-1423337.72*BB23+223819398.05)/1000000 -> 4.454132 | BI23: 16 | BK23: =-4552010+77862.43*AD23-528.064*AD23^2+1.3857*AD23^3 -> 1601460.9 | BL23: =-3210651+145404.1*AE23-2052.163*AE23^2+14.3568*AE23^3 -> 1361925.9 | BM23: =IF(BK23<140,-737886.6-3612.887*AF23+84.47319*AF23^2,7040924-115283.7*AF23+485.2715*AF23^2) -> 691837.31 | BN23: =4001977-66502.13*AG23+275.558*AG23^2 -> 313482.45 | BO23: =12256870-84903.96*AH23+146.7551*AH23^2 -> 208385.94 | BP23: =9095248-135970.3*AI23+510.0572*AI23^2 -> 497848.61 | BQ23: =IF(BO23<73.2,-180.3+3.1*AJ23,312.46-10.83*AJ23+0.098*AJ23^2)*10000 -> 678121.05 | BR23: =(219.28*AK23^2-173172.2*AK23+34168761.89) -> 225789.71 | BS23: =5190570-498758.9*AL23+14528.53*AL23^2-112.5*AL23^3 -> 91444.775 | BT23: =(207.86-3.07416*AM23+0.00297*AM23^2+0.000073*AM23^3)*10000 -> 190742.86 | BU23: =(412.37-12.56*AN23+0.12278*AN23^2-0.000376*AN23^3)*10000 -> 168170.34 | BV23: =(5708324-41094.23*AO23+72.7745*AO23^2) -> 150278.5 | BW23: =(1307.749-5.30998*AP23+0.005386*AP23^2)*10000 -> 106652.97 | BX23: =(33.36079-1.57235*AQ23+0.020673*AQ23^2-0.000067*AQ23^3)*10000 -> 96774.683 | BY23: =(-106.619+3.872392*AR23-0.0491*AR23^2+0.000219*AR23^3)*10000 -> 84902.277 | BZ23: =(-2923.33+10.10447*AS23-0.00872*AS23^2)*10000 -> 32593.858 | CA23: =(149.6647-3.26844*AT23+0.02264*AT23^2-0.000048*AT23^3)*10000 -> 40161.559
B24: 17 | C24: F | D24: =ROUND(IF(AD24<205,SUM(-320030000,6636771*AD24,-46046*AD24^2,106.62*AD24^3),SUM(91660160,1216002*AD24,-22168*AD24^2,71.366*AD24^3))/1000000,3) -> 39.775 | E24: =ROUND((6669048.41-363409.186*AE24-307.876*AE24^2+152.3398*AE24^3)/1000000,3) -> 19.918 | F24: =ROUND((-98334930.2+3037042.21*AF24-30615.40767*AF24^2+101.23056*AF24^3)/1000000,3) -> 10.636 | G24: =AW24 -> 8.251 | H24: =ROUND((-174502023+4277428*AG24-35009.373*AG24^2+95.58911*AG24^3)/1000000-0.096,3) -> 3.297 | I24: =ROUND(IF(AH24<318,SUM(3.5242*AH24^2-2140.3*AH24+325031)/1000,SUM(70242780-813889.6*AH24+7928.716*AH24^2-35.20719*AH24^3+0.05082853*AH24^4)/1000000)-0.059,3) -> 2.38 | J24: =ROUND((-442650826+9751516.3*AI24-72042.8986*AI24^2+178.4049*AI24^3)/1000000,3)-0.071 -> 5.561 | K24: =ROUND(((4827852-139329.3*AJ24+2797.9*AJ24^2-98.98*AJ24^3+1.14*AJ24^4)/1000000),3)-0.05 -> 6.807 | L24: =ROUND((IF(AK24<424,SUM(5064.49*AK24^2-4133655.98*AK24+843517073.2),(7938.48*AK24^2-6579376.11*AK24+1363834719.7)))/1000000,3) -> 2.13 | M24: =ROUND((-8532018+1417757*AL24-72752.08*AL24^2+1191.92*AL24^3)/1000000,3) -> 0.149 | N24: =ROUND((-98293225+2791565*AM24-26671.1*AM24^2+85.56608*AM24^3)/1000000,3)-0.001 -> 1.906 | O24: =ROUND((-5101113+342273.3*AN24-5950.34*AN24^2+30.97425*AN24^3)/1000000,3)-0 -> 1.957 | P24: =ROUND((352562346-2208805*AO24+3459.655*AO24^2)/1000000,3)-0 -> 1.541 | Q24: =ROUND((426242189-1669663*AP24+1635.186*AP24^2)/1000000,3)+0.033 -> 1.43 | R24: =ROUND((2823894-25900.1*AQ24-1177.84*AQ24^2+13.979*AQ24^3)/1000000,3)-0.005 -> 0.99 | S24: =ROUND((-11518534+483790.5*AR24-6823.11*AR24^2+32.24883*AR24^3)/1000000,3)+0 -> 0.86 | T24: =ROUND((406066983-1465679*AS24+1322.517*AS24^2)/1000000,3)-0.001 -> 0.363 | U24: =ROUND((-13395930+388944*AT24-3702.68*AT24^2+11.59891*AT24^3)/1000000,3)-0 -> 0.298 | V24: =SUM(D24:U24) -> 108.249 | W24: =D24+H24+I24+J24+K24+L24+N24+M24 -> 62.005 | AB24: =B24 -> 17 | AC24: =C24 -> F | AD24: 216.32 | AE24: 62.48 | AF24: 150.87 | AG24: 155.1 | AH24: 329.07 | AI24: 163.54 | AJ24: 78.96 | AK24: 428.3 | AL24: =$AL$3+4.01 -> 26.75 | AM24: 130.25 | AN24: 111.11 | AO24: 340.25 | AP24: 539.5 | AQ24: 88.49 | AR24: 99.79 | AS24: 571.1 | AT24: 139.6 | AV24: 401.73 | AW24: 8.251 | AX24: 404.98 | AY24: 2.794 | AZ24: 397.8 | BA24: 2 | BB24: 359.5 | BC24: =(2261.87*BB24^2-1423337.72*BB24+223819398.05)/1000000 -> 4.454132 | BI24: 17 | BK24: =-4552010+77862.43*AD24-528.064*AD24^2+1.3857*AD24^3 -> 1607603.7 | BL24: =-3210651+145404.1*AE24-2052.163*AE24^2+14.3568*AE24^3 -> 1364779.4 | BM24: =IF(BK24<140,-737886.6-3612.887*AF24+84.47319*AF24^2,7040924-115283.7*AF24+485.2715*AF24^2) -> 693704.09 | BN24: =4001977-66502.13*AG24+275.558*AG24^2 -> 316322.64 | BO24: =12256870-84903.96*AH24+146.7551*AH24^2 -> 209202.92 | BP24: =9095248-135970.3*AI24+510.0572*AI24^2 -> 500314.09 | BQ24: =IF(BO24<73.2,-180.3+3.1*AJ24,312.46-10.83*AJ24+0.098*AJ24^2)*10000 -> 683219.97 | BR24: =(219.28*AK24^2-173172.2*AK24+34168761.89) -> 224026.99 | BS24: =5190570-498758.9*AL24+14528.53*AL24^2-112.5*AL24^3 -> 91444.775 | BT24: =(207.86-3.07416*AM24+0.00297*AM24^2+0.000073*AM24^3)*10000 -> 191449.51 | BU24: =(412.37-12.56*AN24+0.12278*AN24^2-0.000376*AN24^3)*10000 -> 168409.92 | BV24: =(5708324-41094.23*AO24+72.7745*AO24^2) -> 151120.66 | BW24: =(1307.749-5.30998*AP24+0.005386*AP24^2)*10000 -> 106652.97 | BX24: =(33.36079-1.57235*AQ24+0.020673*AQ24^2-0.000067*AQ24^3)*10000 -> 96774.683 | BY24: =(-106.619+3.872392*AR24-0.0491*AR24^2+0.000219*AR24^3)*10000 -> 84902.277 | BZ24: =(-2923.33+10.10447*AS24-0.00872*AS24^2)*10000 -> 32593.858 | CA24: =(149.6647-3.26844*AT24+0.02264*AT24^2-0.000048*AT24^3)*10000 -> 40161.559
B25: 18 | C25: S | AB25: =B25 -> 18 | AC25: =C25 -> S | BI25: 18 | BK25: =-4552010+77862.43*AD25-528.064*AD25^2+1.3857*AD25^3 -> -4552010 | BL25: =-3210651+145404.1*AE25-2052.163*AE25^2+14.3568*AE25^3 -> -3210651 | BM25: =IF(BK25<140,-737886.6-3612.887*AF25+84.47319*AF25^2,7040924-115283.7*AF25+485.2715*AF25^2) -> -737886.6 | BN25: =4001977-66502.13*AG25+275.558*AG25^2 -> 4001977 | BO25: =12256870-84903.96*AH25+146.7551*AH25^2 -> 12256870 | BP25: =9095248-135970.3*AI25+510.0572*AI25^2 -> 9095248 | BQ25: =IF(BO25<73.2,-180.3+3.1*AJ25,312.46-10.83*AJ25+0.098*AJ25^2)*10000 -> 3124600 | BR25: =(219.28*AK25^2-173172.2*AK25+34168761.89) -> 34168762 | BS25: =5190570-498758.9*AL25+14528.53*AL25^2-112.5*AL25^3 -> 5190570 | BT25: =(207.86-3.07416*AM25+0.00297*AM25^2+0.000073*AM25^3)*10000 -> 2078600 | BU25: =(412.37-12.56*AN25+0.12278*AN25^2-0.000376*AN25^3)*10000 -> 4123700 | BV25: =(5708324-41094.23*AO25+72.7745*AO25^2) -> 5708324 | BW25: =(1307.749-5.30998*AP25+0.005386*AP25^2)*10000 -> 13077490 | BX25: =(33.36079-1.57235*AQ25+0.020673*AQ25^2-0.000067*AQ25^3)*10000 -> 333607.9 | BY25: =(-106.619+3.872392*AR25-0.0491*AR25^2+0.000219*AR25^3)*10000 -> -1066190 | BZ25: =(-2923.33+10.10447*AS25-0.00872*AS25^2)*10000 -> -29233300 | CA25: =(149.6647-3.26844*AT25+0.02264*AT25^2-0.000048*AT25^3)*10000 -> 1496647
B26: 19 | C26: S | AB26: =B26 -> 19 | AC26: =C26 -> S | BI26: 19 | BK26: =-4552010+77862.43*AD26-528.064*AD26^2+1.3857*AD26^3 -> -4552010 | BL26: =-3210651+145404.1*AE26-2052.163*AE26^2+14.3568*AE26^3 -> -3210651 | BM26: =IF(BK26<140,-737886.6-3612.887*AF26+84.47319*AF26^2,7040924-115283.7*AF26+485.2715*AF26^2) -> -737886.6 | BN26: =4001977-66502.13*AG26+275.558*AG26^2 -> 4001977 | BO26: =12256870-84903.96*AH26+146.7551*AH26^2 -> 12256870 | BP26: =9095248-135970.3*AI26+510.0572*AI26^2 -> 9095248 | BQ26: =IF(BO26<73.2,-180.3+3.1*AJ26,312.46-10.83*AJ26+0.098*AJ26^2)*10000 -> 3124600 | BR26: =(219.28*AK26^2-173172.2*AK26+34168761.89) -> 34168762 | BS26: =5190570-498758.9*AL26+14528.53*AL26^2-112.5*AL26^3 -> 5190570 | BT26: =(207.86-3.07416*AM26+0.00297*AM26^2+0.000073*AM26^3)*10000 -> 2078600 | BU26: =(412.37-12.56*AN26+0.12278*AN26^2-0.000376*AN26^3)*10000 -> 4123700 | BV26: =(5708324-41094.23*AO26+72.7745*AO26^2) -> 5708324 | BW26: =(1307.749-5.30998*AP26+0.005386*AP26^2)*10000 -> 13077490 | BX26: =(33.36079-1.57235*AQ26+0.020673*AQ26^2-0.000067*AQ26^3)*10000 -> 333607.9 | BY26: =(-106.619+3.872392*AR26-0.0491*AR26^2+0.000219*AR26^3)*10000 -> -1066190 | BZ26: =(-2923.33+10.10447*AS26-0.00872*AS26^2)*10000 -> -29233300 | CA26: =(149.6647-3.26844*AT26+0.02264*AT26^2-0.000048*AT26^3)*10000 -> 1496647
B27: 20 | C27: M | D27: =ROUND(IF(AD27<205,SUM(-320030000,6636771*AD27,-46046*AD27^2,106.62*AD27^3),SUM(91660160,1216002*AD27,-22168*AD27^2,71.366*AD27^3))/1000000,3) -> 41.24 | E27: =ROUND((6669048.41-363409.186*AE27-307.876*AE27^2+152.3398*AE27^3)/1000000,3) -> 20.21 | F27: =ROUND((-98334930.2+3037042.21*AF27-30615.40767*AF27^2+101.23056*AF27^3)/1000000,3) -> 10.764 | G27: =AW27 -> 8.317 | H27: =ROUND((-174502023+4277428*AG27-35009.373*AG27^2+95.58911*AG27^3)/1000000-0.096,3) -> 3.47 | I27: =ROUND(IF(AH27<318,SUM(3.5242*AH27^2-2140.3*AH27+325031)/1000,SUM(70242780-813889.6*AH27+7928.716*AH27^2-35.20719*AH27^3+0.05082853*AH27^4)/1000000)-0.059,3) -> 2.419 | J27: =ROUND((-442650826+9751516.3*AI27-72042.8986*AI27^2+178.4049*AI27^3)/1000000,3)-0.071 -> 5.682 | K27: =ROUND(((4827852-139329.3*AJ27+2797.9*AJ27^2-98.98*AJ27^3+1.14*AJ27^4)/1000000),3)-0.05 -> 7.039 | L27: =ROUND((IF(AK27<424,SUM(5064.49*AK27^2-4133655.98*AK27+843517073.2),(7938.48*AK27^2-6579376.11*AK27+1363834719.7)))/1000000,3) -> 1.501 | M27: =ROUND((-8532018+1417757*AL27-72752.08*AL27^2+1191.92*AL27^3)/1000000,3) -> 0.149 | N27: =ROUND((-98293225+2791565*AM27-26671.1*AM27^2+85.56608*AM27^3)/1000000,3)-0.001 -> 1.921 | O27: =ROUND((-5101113+342273.3*AN27-5950.34*AN27^2+30.97425*AN27^3)/1000000,3)-0 -> 1.974 | P27: =ROUND((352562346-2208805*AO27+3459.655*AO27^2)/1000000,3)-0 -> 1.6 | Q27: =ROUND((426242189-1669663*AP27+1635.186*AP27^2)/1000000,3)+0.033 -> 1.425 | R27: =ROUND((2823894-25900.1*AQ27-1177.84*AQ27^2+13.979*AQ27^3)/1000000,3)-0.005 -> 0.99 | S27: =ROUND((-11518534+483790.5*AR27-6823.11*AR27^2+32.24883*AR27^3)/1000000,3)+0 -> 0.86 | T27: =ROUND((406066983-1465679*AS27+1322.517*AS27^2)/1000000,3)-0.001 -> 0.363 | U27: =ROUND((-13395930+388944*AT27-3702.68*AT27^2+11.59891*AT27^3)/1000000,3)-0 -> 0.298 | V27: =SUM(D27:U27) -> 110.222 | W27: =D27+H27+I27+J27+K27+L27+N27+M27 -> 63.421 | AB27: =B27 -> 20 | AC27: =C27 -> M | AD27: 217.2 | AE27: 62.69 | AF27: 151.05 | AG27: 155.64 | AH27: 329.25 | AI27: 163.78 | AJ27: 79.29 | AK27: 425.08 | AL27: =$AL$3+4.01 -> 26.75 | AM27: 130.33 | AN27: 111.21 | AO27: 340.65 | AP27: 539.45 | AQ27: 88.49 | AR27: 99.79 | AS27: 571.1 | AT27: 139.6 | AV27: 401.85 | AW27: 8.317 | AX27: 405 | AY27: 2.8 | AZ27: 397.8 | BA27: 2 | BB27: 359.5 | BC27: =(2261.87*BB27^2-1423337.72*BB27+223819398.05)/1000000 -> 4.454132 | BI27: 20 | BK27: =-4552010+77862.43*AD27-528.064*AD27^2+1.3857*AD27^3 -> 1646550.2 | BL27: =-3210651+145404.1*AE27-2052.163*AE27^2+14.3568*AE27^3 -> 1376799.1 | BM27: =IF(BK27<140,-737886.6-3612.887*AF27+84.47319*AF27^2,7040924-115283.7*AF27+485.2715*AF27^2) -> 699325.4 | BN27: =4001977-66502.13*AG27+275.558*AG27^2 -> 326650.01 | BO27: =12256870-84903.96*AH27+146.7551*AH27^2 -> 211310.34 | BP27: =9095248-135970.3*AI27+510.0572*AI27^2 -> 507749.68 | BQ27: =IF(BO27<73.2,-180.3+3.1*AJ27,312.46-10.83*AJ27+0.098*AJ27^2)*10000 -> 698659.02 | BR27: =(219.28*AK27^2-173172.2*AK27+34168761.89) -> 179085.56 | BS27: =5190570-498758.9*AL27+14528.53*AL27^2-112.5*AL27^3 -> 91444.775 | BT27: =(207.86-3.07416*AM27+0.00297*AM27^2+0.000073*AM27^3)*10000 -> 192583.43 | BU27: =(412.37-12.56*AN27+0.12278*AN27^2-0.000376*AN27^3)*10000 -> 169208.19 | BV27: =(5708324-41094.23*AO27+72.7745*AO27^2) -> 154503.83 | BW27: =(1307.749-5.30998*AP27+0.005386*AP27^2)*10000 -> 106402.34 | BX27: =(33.36079-1.57235*AQ27+0.020673*AQ27^2-0.000067*AQ27^3)*10000 -> 96774.683 | BY27: =(-106.619+3.872392*AR27-0.0491*AR27^2+0.000219*AR27^3)*10000 -> 84902.277 | BZ27: =(-2923.33+10.10447*AS27-0.00872*AS27^2)*10000 -> 32593.858 | CA27: =(149.6647-3.26844*AT27+0.02264*AT27^2-0.000048*AT27^3)*10000 -> 40161.559
B28: 21 | C28: T | D28: =ROUND(IF(AD28<205,SUM(-320030000,6636771*AD28,-46046*AD28^2,106.62*AD28^3),SUM(91660160,1216002*AD28,-22168*AD28^2,71.366*AD28^3))/1000000,3) -> 41.477 | E28: =ROUND((6669048.41-363409.186*AE28-307.876*AE28^2+152.3398*AE28^3)/1000000,3) -> 20.293 | F28: =ROUND((-98334930.2+3037042.21*AF28-30615.40767*AF28^2+101.23056*AF28^3)/1000000,3) -> 10.807 | G28: =AW28 -> 8.333 | H28: =ROUND((-174502023+4277428*AG28-35009.373*AG28^2+95.58911*AG28^3)/1000000-0.096,3) -> 3.509 | I28: =ROUND(IF(AH28<318,SUM(3.5242*AH28^2-2140.3*AH28+325031)/1000,SUM(70242780-813889.6*AH28+7928.716*AH28^2-35.20719*AH28^3+0.05082853*AH28^4)/1000000)-0.059,3) -> 2.43 | J28: =ROUND((-442650826+9751516.3*AI28-72042.8986*AI28^2+178.4049*AI28^3)/1000000,3)-0.071 -> 5.718 | K28: =ROUND(((4827852-139329.3*AJ28+2797.9*AJ28^2-98.98*AJ28^3+1.14*AJ28^4)/1000000),3)-0.05 -> 7.074 | L28: =ROUND((IF(AK28<424,SUM(5064.49*AK28^2-4133655.98*AK28+843517073.2),(7938.48*AK28^2-6579376.11*AK28+1363834719.7)))/1000000,3) -> 1.51 | M28: =ROUND((-8532018+1417757*AL28-72752.08*AL28^2+1191.92*AL28^3)/1000000,3) -> 0.149 | N28: =ROUND((-98293225+2791565*AM28-26671.1*AM28^2+85.56608*AM28^3)/1000000,3)-0.001 -> 1.933 | O28: =ROUND((-5101113+342273.3*AN28-5950.34*AN28^2+30.97425*AN28^3)/1000000,3)-0 -> 1.974 | P28: =ROUND((352562346-2208805*AO28+3459.655*AO28^2)/1000000,3)-0 -> 1.622 | Q28: =ROUND((426242189-1669663*AP28+1635.186*AP28^2)/1000000,3)+0.033 -> 1.426 | R28: =ROUND((2823894-25900.1*AQ28-1177.84*AQ28^2+13.979*AQ28^3)/1000000,3)-0.005 -> 0.99 | S28: =ROUND((-11518534+483790.5*AR28-6823.11*AR28^2+32.24883*AR28^3)/1000000,3)+0 -> 0.86 | T28: =ROUND((406066983-1465679*AS28+1322.517*AS28^2)/1000000,3)-0.001 -> 0.363 | U28: =ROUND((-13395930+388944*AT28-3702.68*AT28^2+11.59891*AT28^3)/1000000,3)-0 -> 0.298 | V28: =SUM(D28:U28) -> 110.766 | W28: =D28+H28+I28+J28+K28+L28+N28+M28 -> 63.8 | AB28: =B28 -> 21 | AC28: =C28 -> T | AD28: 217.34 | AE28: 62.75 | AF28: 151.11 | AG28: 155.76 | AH28: 329.3 | AI28: 163.85 | AJ28: 79.34 | AK28: 425.13 | AL28: =$AL$3+4.01 -> 26.75 | AM28: 130.39 | AN28: 111.21 | AO28: 340.8 | AP28: 539.46 | AQ28: 88.49 | AR28: 99.79 | AS28: 571.1 | AT28: 139.6 | AV28: 401.88 | AW28: 8.333 | AX28: 405 | AY28: 2.8 | AZ28: 397.8 | BA28: 2 | BB28: 359.5 | BC28: =(2261.87*BB28^2-1423337.72*BB28+223819398.05)/1000000 -> 4.454132 | BI28: 21 | BK28: =-4552010+77862.43*AD28-528.064*AD28^2+1.3857*AD28^3 -> 1652799.6 | BL28: =-3210651+145404.1*AE28-2052.163*AE28^2+14.3568*AE28^3 -> 1380243.7 | BM28: =IF(BK28<140,-737886.6-3612.887*AF28+84.47319*AF28^2,7040924-115283.7*AF28+485.2715*AF28^2) -> 701206.16 | BN28: =4001977-66502.13*AG28+275.558*AG28^2 -> 328966.81 | BO28: =12256870-84903.96*AH28+146.7551*AH28^2 -> 211897.42 | BP28: =9095248-135970.3*AI28+510.0572*AI28^2 -> 509929.46 | BQ28: =IF(BO28<73.2,-180.3+3.1*AJ28,312.46-10.83*AJ28+0.098*AJ28^2)*10000 -> 701016.89 | BR28: =(219.28*AK28^2-173172.2*AK28+34168761.89) -> 179748.65 | BS28: =5190570-498758.9*AL28+14528.53*AL28^2-112.5*AL28^3 -> 91444.775 | BT28: =(207.86-3.07416*AM28+0.00297*AM28^2+0.000073*AM28^3)*10000 -> 193436.51 | BU28: =(412.37-12.56*AN28+0.12278*AN28^2-0.000376*AN28^3)*10000 -> 169208.19 | BV28: =(5708324-41094.23*AO28+72.7745*AO28^2) -> 155778.52 | BW28: =(1307.749-5.30998*AP28+0.005386*AP28^2)*10000 -> 106452.45 | BX28: =(33.36079-1.57235*AQ28+0.020673*AQ28^2-0.000067*AQ28^3)*10000 -> 96774.683 | BY28: =(-106.619+3.872392*AR28-0.0491*AR28^2+0.000219*AR28^3)*10000 -> 84902.277 | BZ28: =(-2923.33+10.10447*AS28-0.00872*AS28^2)*10000 -> 32593.858 | CA28: =(149.6647-3.26844*AT28+0.02264*AT28^2-0.000048*AT28^3)*10000 -> 40161.559
